Workbook

Sheet Cronograma
A1: Puestos | B1: Nocturno | C1: 46023 | D1: 46024 | E1: 46025 | F1: 46026 | G1: 46027 | H1: 46028 | I1: 46029 | J1: 46030 | K1: 46031 | L1: 46032 | M1: 46033 | N1: 46034 | O1: 46035 | P1: 46036 | Q1: 46037
A2: D - L1 | B2: FALSE | C2: Diana Carolina Molina | D2: Diana Carolina Molina | E2: Xiomara | F2: Alba Becerra | G2: Diana Carolina Molina | H2: Diana Carolina Molina | I2: Diana Carolina Molina | J2: Diana Carolina Molina | K2: Diana Carolina Molina | L2: Betsy Mauribel | M2: Alba Becerra | N2: Diana Carolina Molina | O2: Diana Carolina Molina | P2: Diana Carolina Molina | Q2: Diana Carolina Molina
A3: D - L3 | B3: FALSE | C3: Yenifer | D3: Alba Becerra | E3: Rosa Angelica | F3: Rosa Angelica | G3: Luisa Viviana | H3: Alba Becerra | I3: Alba Becerra | J3: Anyelis | K3: Anyelis | L3: Gilvert | M3: Gilvert | N3: Elisa Parra | O3: Elisa Parra | P3: Elisa Parra | Q3: Anyelis
A4: D - L5 | B4: FALSE | C4: Efigenia | D4: Efigenia | E4: Efigenia | F4: Efigenia | G4: Xiomara | H4: Efigenia | I4: Efigenia | J4: Efigenia | K4: Efigenia | L4: Efigenia | M4: Betsy Mauribel | N4: Betsy Mauribel | O4: Betsy Mauribel | P4: Betsy Mauribel | Q4: Efigenia
A5: D - L7 | B5: FALSE | C5: Alba Becerra | D5: Angie Castillo | E5: Angie Castillo | F5: Angie Castillo | G5: Anyelis | H5: Darcy Lorena | I5: Darcy Lorena | J5: Darcy Lorena | K5: Dora | L5: Dora | M5: Darcy Lorena | N5: Darcy Lorena | O5: Darcy Lorena | P5: Darcy Lorena | Q5: Darcy Lorena
A6: D - L8 | B6: FALSE | C6: Angie Castillo | D6: Dora | E6: Alba Becerra | F6: Dora | G6: German Avila | H6: German Avila | I6: German Avila | J6: German Avila | K6: German Avila | M6: German Avila | N6: German Avila | O6: German Avila | P6: German Avila | Q6: German Avila
A7: D - L9 | B7: FALSE | C7: Dora | D7: Luisa Viviana | E7: Dora | F7: Xiomara | G7: Darcy Lorena | H7: Anyelis | I7: Dora | J7: Dora | K7: Darcy Lorena | L7: Alba Becerra | M7: Elisa Parra | N7: Anyelis | O7: Anyelis | P7: Anyelis | Q7: Dora
A8: D - L11 | B8: FALSE | C8: Xiomara | D8: Rosa Angelica | E8: Luisa Viviana | F8: Luisa Viviana | G8: Rosa Angelica | H8: Xiomara | I8: Anyelis | J8: Alba Becerra | K8: Adanies | L8: Elisa Parra | M8: Anyelis | N8: Gilvert | O8: Gilvert | P8: Gilvert | Q8: Alba Becerra
A9: D - Supervisor | B9: FALSE | C9: Gisela | D9: Martha | E9: Martha | F9: Gisela | G9: Gisela | H9: Martha | I9: Martha | J9: Gisela | K9: Gisela | L9: Martha | M9: Martha | N9: Gisela | O9: Gisela | P9: Martha | Q9: Martha
A10: D - Cocina | B10: FALSE | C10: Adriana | D10: Adriana | E10: Adriana | F10: Adriana | G10: Adriana | H10: Luz Mery | I10: Adriana | J10: Adriana | K10: Adriana | L10: Adriana | M10: Adriana | N10: Luz Mery | O10: Adriana | P10: Adriana | Q10: Adriana
A11: D - Cocina 2 | B11: FALSE | C11: Claudia Patricia | D11: Claudia Patricia | E11: Claudia Patricia | F11: Claudia Patricia | G11: Claudia Patricia | I11: Claudia Patricia | J11: Claudia Patricia | K11: Claudia Patricia | L11: Claudia Patricia | M11: Claudia Patricia | O11: Claudia Patricia | P11: Claudia Patricia | Q11: Claudia Patricia
A12: D - Cocina 3 | B12: FALSE | C12: Luz Estela | D12: Luz Estela | E12: Luz Estela | F12: Luz Estela | G12: Luz Estela | I12: Jeferson | J12: Ofelia | K12: Ofelia | L12: Ofelia | M12: Ofelia | N12: Ofelia | O12: Jeferson | P12: Ofelia | Q12: Ofelia
A13: D - Barra | B13: FALSE | C13: Carolina | D13: Carolina | E13: Carolina | F13: Carolina | G13: Carolina | H13: Maria Naydu | I13: Maria Naydu | J13: Maria Naydu | K13: Maria Naydu | L13: Maria Naydu | M13: Adanies | N13: Adanies | O13: Adanies | P13: Maria Alejandra | Q13: Maria Alejandra
A14: D - Salón | B14: FALSE | C14: Maria Naydu | D14: Maria Naydu | E14: Maria Naydu | F14: Maria Naydu | G14: Maria Alejandra | H14: Maria Alejandra | I14: Maria Alejandra | J14: Maria Alejandra | K14: Maria Alejandra | L14: Luz Mery | M14: Maria Alejandra | N14: Maria Alejandra | O14: Maria Alejandra | P14: Carolina | Q14: Carolina
A15: D - Aseo | B15: FALSE | C15: Tatiana | D15: Tatiana | E15: Tatiana | F15: Tatiana | G15: Tatiana | H15: Dora | I15: Tatiana | J15: Tatiana | K15: Tatiana | L15: Tatiana | M15: Tatiana | N15: Dora | O15: Dora | P15: Tatiana | Q15: Tatiana
A16: D - Caja | B16: FALSE | C16: Angie Marcela | D16: Angie Marcela | E16: Angie Marcela | F16: Angie Marcela | G16: Rosalba | H16: Rosalba | I16: Rosalba | J16: Rosalba | K16: Rosalba | L16: Adanies | M16: Rosalba | N16: Rosalba | O16: Rosalba | P16: Rosalba | Q16: Rosalba
A17: D - Dulcería | B17: FALSE | C17: Luz Mery | D17: Luz Mery | E17: Luz Mery | F17: Luz Mery | G17: Angie Castillo | I17: Angie Castillo | J17: Angie Castillo | K17: Angie Castillo | L17: Angie Castillo | M17: Luz Mery | N17: Angie Castillo | O17: Angie Castillo | P17: Angie Castillo | Q17: Angie Castillo
A18: D - Bodega | B18: FALSE | C18: Jeferson | D18: Jeferson | E18: Jeferson | F18: Jeferson | G18: Jeferson | I18: Luz Mery | J18: Luz Mery | K18: Jeferson | L18: Jeferson | M18: Jeferson | N18: Jeferson | O18: Luz Mery | P18: Luz Mery | Q18: Jeferson
A19: D - Administrador | B19: FALSE | C19: Claudia Milena | D19: Claudia Milena | E19: Claudia Milena | F19: Claudia Milena | G19: Claudia Milena | I19: Claudia Milena | J19: Claudia Milena | K19: Claudia Milena | L19: Claudia Milena | M19: Claudia Milena | O19: Claudia Milena | P19: Claudia Milena | Q19: Claudia Milena
A20: D - Mensajería | B20: FALSE | C20: Victor Julio | D20: Victor Julio | E20: Victor Julio | F20: Victor Julio | G20: Victor Julio | I20: Victor Julio | J20: Victor Julio | K20: Victor Julio | L20: Victor Julio | M20: Victor Julio | O20: Victor Julio | P20: Victor Julio | Q20: Victor Julio
A21: N - L1 | B21: TRUE | C21: Elisa Parra | D21: Anyelis | E21: Elisa Parra | F21: Betsy Mauribel | G21: Maria Paula | H21: Maria Paula | I21: Stefany | J21: Maria Paula | K21: Maria Paula | L21: Maria Paula | M21: Maria Paula | N21: Maria Paula | O21: Maribel | P21: Maribel | Q21: Maria Paula
A22: N - L3 | B22: TRUE | C22: Gilvert | D22: Adanies | E22: Erika Mayerlli | F22: Maribel | G22: Betsy Mauribel | H22: Betsy Mauribel | I22: Elisa Parra | J22: Rosa Angelica | K22: Rosa Angelica | L22: Rosa Angelica | M22: Rosa Angelica | N22: Erika Mayerlli | O22: Rosa Angelica | P22: Rosa Angelica | Q22: Rosa Angelica
A23: N - L5 | B23: TRUE | C23: Betsy Mauribel | D23: Maria Paula | E23: Maribel | F23: Yenifer | G23: Yenifer | H23: Gilvert | I23: Betsy Mauribel | J23: Erika Mayerlli | K23: Erika Mayerlli | L23: Erika Mayerlli | M23: Xiomara | P23: Erika Mayerlli | Q23: Erika Mayerlli
A24: N - L7 | B24: TRUE | C24: Anyelis | D24: Darcy Lorena | E24: Betsy Mauribel | F24: Elisa Parra | G24: Elisa Parra | H24: Erika Mayerlli | I24: Gilvert | J24: Maribel | K24: Stefany | L24: Maribel | M24: Erika Mayerlli | N24: Stefany | P24: Maria Paula | Q24: Adanies
A25: N - L8 | B25: TRUE | C25: German Avila | D25: German Avila | E25: Gilvert | F25: Gilvert | G25: Maribel | H25: Maribel | I25: Rosa Angelica | J25: Stefany | K25: Yenifer | L25: Yenifer | M25: Maribel | N25: Maribel | O25: Stefany | P25: Stefany | Q25: Yenifer
A26: N - L9 | B26: TRUE | C26: Darcy Lorena | D26: Maribel | E26: Maria Paula | F26: Erika Mayerlli | G26: Erika Mayerlli | H26: Elisa Parra | I26: Yenifer | J26: Luisa Viviana | K26: Luisa Viviana | L26: Luisa Viviana | M26: Luisa Viviana | N26: Yenifer | O26: Yenifer | P26: Luisa Viviana | Q26: Luisa Viviana
A27: N - L11 | B27: TRUE | C27: Erika Mayerlli | D27: Stefany | E27: Yenifer | F27: Maria Paula | G27: Gilvert | H27: Yenifer | I27: Luisa Viviana | J27: Xiomara | K27: Xiomara | L27: Xiomara | M27: Yenifer | N27: Xiomara | O27: Luisa Viviana | P27: Xiomara | Q27: Xiomara
A28: N - Cocina | B28: TRUE | C28: Ofelia | D28: Ofelia | E28: Ofelia | F28: Ofelia | G28: Ofelia | I28: Luz Estela | J28: Luz Estela | K28: Luz Estela | L28: Luz Estela | M28: Luz Estela | O28: Luz Estela | P28: Luz Estela | Q28: Luz Estela
A29: N - Caja | B29: TRUE | C29: Rosalba | D29: Rosalba | E29: Stefany | F29: Stefany | G29: Stefany | H29: Angie Marcela | I29: Angie Marcela | J29: Angie Marcela | K29: Angie Marcela | L29: Angie Marcela | M29: Stefany | N29: Angie Marcela | O29: Angie Marcela | P29: Angie Marcela | Q29: Angie Marcela
A30: N - Barra y salón | B30: TRUE | C30: Maria Alejandra | D30: Maria Alejandra | E30: Adanies | F30: Adanies | G30: Adanies | H30: Adanies | I30: Carolina | J30: Carolina | K30: Carolina | L30: Carolina | M30: Carolina | N30: Maria Naydu | O30: Maria Naydu | P30: Maria Naydu | Q30: Maria Naydu

Sheet Empleados
A1: Nombre | B1: Día | C1: Noche | D1: Descanso | E1: 46023 | F1: 46024 | G1: 46025 | H1: 46026 | I1: 46027 | J1: 46028 | K1: 46029 | L1: 46030 | M1: 46031 | N1: 46032 | O1: 46033 | P1: 46034 | Q1: 46035 | R1: 46036 | S1: 46037
A2: Adanies | B2: =SUMPRODUCT((Cronograma!B2:B30=FALSE) * (COUNTIF(E2:S2, Cronograma!A2:A30))) -> 0 | C2: =SUMPRODUCT((Cronograma!B2:B30=TRUE) * (COUNTIF(E2:S2, Cronograma!A2:A30))) -> 0 | D2: =SUM(((SUMPRODUCT((Cronograma!C$2:C$30=$A2)*1)=0)*NOT(SUMPRODUCT((Cronograma!D$2:D$30=$A2)*(Cronograma!$B$2:$B$30=FALSE))>0)),(((SUMPRODUCT((Cronograma!D$2:D$30=$A2)*1)=0)*NOT(SUMPRODUCT((Cronograma!C$2:C$30=$A2)*(Cronograma!$B$2:$B$30=TRUE))>0))+((SUMPRODUCT((Cronograma!D$2:D$30=$A2)*1)=0)*NOT(SUMPRODUCT((Cronograma!E$2:E$30=$A2)*(Cronograma!$B$2:$B$30=FALSE))>0))>0),(((SUMPRODUCT((Cronograma!E$2:E$30=$A2)*1)=0)*NOT(SUMPRODUCT((Cronograma!D$2:D$30=$A2)*(Cronograma!$B$2:$B$30=TRUE))>0))+((SUMPRODUCT((Cronograma!E$2:E$30=$A2)*1)=0)*NOT(SUMPRODUCT((Cronograma!F$2:F$30=$A2)*(Cronograma!$B$2:$B$30=FALSE))>0))>0),(((SUMPRODUCT((Cronograma!F$2:F$30=$A2)*1)=0)*NOT(SUMPRODUCT((Cronograma!E$2:E$30=$A2)*(Cronograma!$B$2:$B$30=TRUE))>0))+((SUMPRODUCT((Cronograma!F$2:F$30=$A2)*1)=0)*NOT(SUMPRODUCT((Cronograma!G$2:G$30=$A2)*(Cronograma!$B$2:$B$30=FALSE))>0))>0),(((SUMPRODUCT((Cronograma!G$2:G$30=$A2)*1)=0)*NOT(SUMPRODUCT((Cronograma!F$2:F$30=$A2)*(Cronograma!$B$2:$B$30=TRUE))>0))+((SUMPRODUCT((Cronograma!G$2:G$30=$A2)*1)=0)*NOT(SUMPRODUCT((Cronograma!H$2:H$30=$A2)*(Cronograma!$B$2:$B$30=FALSE))>0))>0),(((SUMPRODUCT((Cronograma!H$2:H$30=$A2)*1)=0)*NOT(SUMPRODUCT((Cronograma!G$2:G$30=$A2)*(Cronograma!$B$2:$B$30=TRUE))>0))+((SUMPRODUCT((Cronograma!H$2:H$30=$A2)*1)=0)*NOT(SUMPRODUCT((Cronograma!I$2:I$30=$A2)*(Cronograma!$B$2:$B$30=FALSE))>0))>0),(((SUMPRODUCT((Cronograma!I$2:I$30=$A2)*1)=0)*NOT(SUMPRODUCT((Cronograma!H$2:H$30=$A2)*(Cronograma!$B$2:$B$30=TRUE))>0))+((SUMPRODUCT((Cronograma!I$2:I$30=$A2)*1)=0)*NOT(SUMPRODUCT((Cronograma!J$2:J$30=$A2)*(Cronograma!$B$2:$B$30=FALSE))>0))>0),(((SUMPRODUCT((Cronograma!J$2:J$30=$A2)*1)=0)*NOT(SUMPRODUCT((Cronograma!I$2:I$30=$A2)*(Cronograma!$B$2:$B$30=TRUE))>0))+((SUMPRODUCT((Cronograma!J$2:J$30=$A2)*1)=0)*NOT(SUMPRODUCT((Cronograma!K$2:K$30=$A2)*(Cronograma!$B$2:$B$30=FALSE))>0))>0),(((SUMPRODUCT((Cronograma!K$2:K$30=$A2)*1)=0)*NOT(SUMPRODUCT((Cronograma!J$2:J$30=$A2)*(Cronograma!$B$2:$B$30=TRUE))>0))+((SUMPRODUCT((Cronograma!K$2:K$30=$A2)*1)=0)*NOT(SUMPRODUCT((Cronograma!L$2:L$30=$A2)*(Cronograma!$B$2:$B$30=FALSE))>0))>0),(((SUMPRODUCT((Cronograma!L$2:L$30=$A2)*1)=0)*NOT(SUMPRODUCT((Cronograma!K$2:K$30=$A2)*(Cronograma!$B$2:$B$30=TRUE))>0))+((SUMPRODUCT((Cronograma!L$2:L$30=$A2)*1)=0)*NOT(SUMPRODUCT((Cronograma!M$2:M$30=$A2)*(Cronograma!$B$2:$B$30=FALSE))>0))>0),(((SUMPRODUCT((Cronograma!M$2:M$30=$A2)*1)=0)*NOT(SUMPRODUCT((Cronograma!L$2:L$30=$A2)*(Cronograma!$B$2:$B$30=TRUE))>0))+((SUMPRODUCT((Cronograma!M$2:M$30=$A2)*1)=0)*NOT(SUMPRODUCT((Cronograma!N$2:N$30=$A2)*(Cronograma!$B$2:$B$30=FALSE))>0))>0),(((SUMPRODUCT((Cronograma!N$2:N$30=$A2)*1)=0)*NOT(SUMPRODUCT((Cronograma!M$2:M$30=$A2)*(Cronograma!$B$2:$B$30=TRUE))>0))+((SUMPRODUCT((Cronograma!N$2:N$30=$A2)*1)=0)*NOT(SUMPRODUCT((Cronograma!O$2:O$30=$A2)*(Cronograma!$B$2:$B$30=FALSE))>0))>0),(((SUMPRODUCT((Cronograma!O$2:O$30=$A2)*1)=0)*NOT(SUMPRODUCT((Cronograma!N$2:N$30=$A2)*(Cronograma!$B$2:$B$30=TRUE))>0))+((SUMPRODUCT((Cronograma!O$2:O$30=$A2)*1)=0)*NOT(SUMPRODUCT((Cronograma!P$2:P$30=$A2)*(Cronograma!$B$2:$B$30=FALSE))>0))>0),(((SUMPRODUCT((Cronograma!P$2:P$30=$A2)*1)=0)*NOT(SUMPRODUCT((Cronograma!O$2:O$30=$A2)*(Cronograma!$B$2:$B$30=TRUE))>0))+((SUMPRODUCT((Cronograma!P$2:P$30=$A2)*1)=0)*NOT(SUMPRODUCT((Cronograma!Q$2:Q$30=$A2)*(Cronograma!$B$2:$B$30=FALSE))>0))>0),((SUMPRODUCT((Cronograma!Q$2:Q$30=$A2)*1)=0)*NOT(SUMPRODUCT((Cronograma!P$2:P$30=$A2)*(Cronograma!$B$2:$B$30=TRUE))>0))) -> 0 | E2: {=_xlfn.XLOOKUP("Adanies",Cronograma!C2:C30,Cronograma!A2:A30,"")} -> 0 | F2: {=_xlfn.XLOOKUP("Adanies",Cronograma!D2:D30,Cronograma!A2:A30,"")} -> 0 | G2: {=_xlfn.XLOOKUP("Adanies",Cronograma!E2:E30,Cronograma!A2:A30,"")} -> 0 | H2: {=_xlfn.XLOOKUP("Adanies",Cronograma!F2:F30,Cronograma!A2:A30,"")} -> 0 | I2: {=_xlfn.XLOOKUP("Adanies",Cronograma!G2:G30,Cronograma!A2:A30,"")} -> 0 | J2: {=_xlfn.XLOOKUP("Adanies",Cronograma!H2:H30,Cronograma!A2:A30,"")} -> 0 | K2: {=_xlfn.XLOOKUP("Adanies",Cronograma!I2:I30,Cronograma!A2:A30,"")} -> 0 | L2: {=_xlfn.XLOOKUP("Adanies",Cronograma!J2:J30,Cronograma!A2:A30,"")} -> 0 | M2: {=_xlfn.XLOOKUP("Adanies",Cronograma!K2:K30,Cronograma!A2:A30,"")} -> 0 | N2: {=_xlfn.XLOOKUP("Adanies",Cronograma!L2:L30,Cronograma!A2:A30,"")} -> 0 | O2: {=_xlfn.XLOOKUP("Adanies",Cronograma!M2:M30,Cronograma!A2:A30,"")} -> 0 | P2: {=_xlfn.XLOOKUP("Adanies",Cronograma!N2:N30,Cronograma!A2:A30,"")} -> 0 | Q2: {=_xlfn.XLOOKUP("Adanies",Cronograma!O2:O30,Cronograma!A2:A30,"")} -> 0 | R2: {=_xlfn.XLOOKUP("Adanies",Cronograma!P2:P30,Cronograma!A2:A30,"")} -> 0 | S2: {=_xlfn.XLOOKUP("Adanies",Cronograma!Q2:Q30,Cronograma!A2:A30,"")} -> 0
A3: Alba Becerra | B3: =SUMPRODUCT((Cronograma!B2:B30=FALSE) * (COUNTIF(E3:S3, Cronograma!A2:A30))) -> 0 | C3: =SUMPRODUCT((Cronograma!B2:B30=TRUE) * (COUNTIF(E3:S3, Cronograma!A2:A30))) -> 0 | D3: =SUM(((SUMPRODUCT((Cronograma!C$2:C$30=$A3)*1)=0)*NOT(SUMPRODUCT((Cronograma!D$2:D$30=$A3)*(Cronograma!$B$2:$B$30=FALSE))>0)),(((SUMPRODUCT((Cronograma!D$2:D$30=$A3)*1)=0)*NOT(SUMPRODUCT((Cronograma!C$2:C$30=$A3)*(Cronograma!$B$2:$B$30=TRUE))>0))+((SUMPRODUCT((Cronograma!D$2:D$30=$A3)*1)=0)*NOT(SUMPRODUCT((Cronograma!E$2:E$30=$A3)*(Cronograma!$B$2:$B$30=FALSE))>0))>0),(((SUMPRODUCT((Cronograma!E$2:E$30=$A3)*1)=0)*NOT(SUMPRODUCT((Cronograma!D$2:D$30=$A3)*(Cronograma!$B$2:$B$30=TRUE))>0))+((SUMPRODUCT((Cronograma!E$2:E$30=$A3)*1)=0)*NOT(SUMPRODUCT((Cronograma!F$2:F$30=$A3)*(Cronograma!$B$2:$B$30=FALSE))>0))>0),(((SUMPRODUCT((Cronograma!F$2:F$30=$A3)*1)=0)*NOT(SUMPRODUCT((Cronograma!E$2:E$30=$A3)*(Cronograma!$B$2:$B$30=TRUE))>0))+((SUMPRODUCT((Cronograma!F$2:F$30=$A3)*1)=0)*NOT(SUMPRODUCT((Cronograma!G$2:G$30=$A3)*(Cronograma!$B$2:$B$30=FALSE))>0))>0),(((SUMPRODUCT((Cronograma!G$2:G$30=$A3)*1)=0)*NOT(SUMPRODUCT((Cronograma!F$2:F$30=$A3)*(Cronograma!$B$2:$B$30=TRUE))>0))+((SUMPRODUCT((Cronograma!G$2:G$30=$A3)*1)=0)*NOT(SUMPRODUCT((Cronograma!H$2:H$30=$A3)*(Cronograma!$B$2:$B$30=FALSE))>0))>0),(((SUMPRODUCT((Cronograma!H$2:H$30=$A3)*1)=0)*NOT(SUMPRODUCT((Cronograma!G$2:G$30=$A3)*(Cronograma!$B$2:$B$30=TRUE))>0))+((SUMPRODUCT((Cronograma!H$2:H$30=$A3)*1)=0)*NOT(SUMPRODUCT((Cronograma!I$2:I$30=$A3)*(Cronograma!$B$2:$B$30=FALSE))>0))>0),(((SUMPRODUCT((Cronograma!I$2:I$30=$A3)*1)=0)*NOT(SUMPRODUCT((Cronograma!H$2:H$30=$A3)*(Cronograma!$B$2:$B$30=TRUE))>0))+((SUMPRODUCT((Cronograma!I$2:I$30=$A3)*1)=0)*NOT(SUMPRODUCT((Cronograma!J$2:J$30=$A3)*(Cronograma!$B$2:$B$30=FALSE))>0))>0),(((SUMPRODUCT((Cronograma!J$2:J$30=$A3)*1)=0)*NOT(SUMPRODUCT((Cronograma!I$2:I$30=$A3)*(Cronograma!$B$2:$B$30=TRUE))>0))+((SUMPRODUCT((Cronograma!J$2:J$30=$A3)*1)=0)*NOT(SUMPRODUCT((Cronograma!K$2:K$30=$A3)*(Cronograma!$B$2:$B$30=FALSE))>0))>0),(((SUMPRODUCT((Cronograma!K$2:K$30=$A3)*1)=0)*NOT(SUMPRODUCT((Cronograma!J$2:J$30=$A3)*(Cronograma!$B$2:$B$30=TRUE))>0))+((SUMPRODUCT((Cronograma!K$2:K$30=$A3)*1)=0)*NOT(SUMPRODUCT((Cronograma!L$2:L$30=$A3)*(Cronograma!$B$2:$B$30=FALSE))>0))>0),(((SUMPRODUCT((Cronograma!L$2:L$30=$A3)*1)=0)*NOT(SUMPRODUCT((Cronograma!K$2:K$30=$A3)*(Cronograma!$B$2:$B$30=TRUE))>0))+((SUMPRODUCT((Cronograma!L$2:L$30=$A3)*1)=0)*NOT(SUMPRODUCT((Cronograma!M$2:M$30=$A3)*(Cronograma!$B$2:$B$30=FALSE))>0))>0),(((SUMPRODUCT((Cronograma!M$2:M$30=$A3)*1)=0)*NOT(SUMPRODUCT((Cronograma!L$2:L$30=$A3)*(Cronograma!$B$2:$B$30=TRUE))>0))+((SUMPRODUCT((Cronograma!M$2:M$30=$A3)*1)=0)*NOT(SUMPRODUCT((Cronograma!N$2:N$30=$A3)*(Cronograma!$B$2:$B$30=FALSE))>0))>0),(((SUMPRODUCT((Cronograma!N$2:N$30=$A3)*1)=0)*NOT(SUMPRODUCT((Cronograma!M$2:M$30=$A3)*(Cronograma!$B$2:$B$30=TRUE))>0))+((SUMPRODUCT((Cronograma!N$2:N$30=$A3)*1)=0)*NOT(SUMPRODUCT((Cronograma!O$2:O$30=$A3)*(Cronograma!$B$2:$B$30=FALSE))>0))>0),(((SUMPRODUCT((Cronograma!O$2:O$30=$A3)*1)=0)*NOT(SUMPRODUCT((Cronograma!N$2:N$30=$A3)*(Cronograma!$B$2:$B$30=TRUE))>0))+((SUMPRODUCT((Cronograma!O$2:O$30=$A3)*1)=0)*NOT(SUMPRODUCT((Cronograma!P$2:P$30=$A3)*(Cronograma!$B$2:$B$30=FALSE))>0))>0),(((SUMPRODUCT((Cronograma!P$2:P$30=$A3)*1)=0)*NOT(SUMPRODUCT((Cronograma!O$2:O$30=$A3)*(Cronograma!$B$2:$B$30=TRUE))>0))+((SUMPRODUCT((Cronograma!P$2:P$30=$A3)*1)=0)*NOT(SUMPRODUCT((Cronograma!Q$2:Q$30=$A3)*(Cronograma!$B$2:$B$30=FALSE))>0))>0),((SUMPRODUCT((Cronograma!Q$2:Q$30=$A3)*1)=0)*NOT(SUMPRODUCT((Cronograma!P$2:P$30=$A3)*(Cronograma!$B$2:$B$30=TRUE))>0))) -> 0 | E3: {=_xlfn.XLOOKUP("Alba Becerra",Cronograma!C2:C30,Cronograma!A2:A30,"")} -> 0 | F3: {=_xlfn.XLOOKUP("Alba Becerra",Cronograma!D2:D30,Cronograma!A2:A30,"")} -> 0 | G3: {=_xlfn.XLOOKUP("Alba Becerra",Cronograma!E2:E30,Cronograma!A2:A30,"")} -> 0 | H3: {=_xlfn.XLOOKUP("Alba Becerra",Cronograma!F2:F30,Cronograma!A2:A30,"")} -> 0 | I3: {=_xlfn.XLOOKUP("Alba Becerra",Cronograma!G2:G30,Cronograma!A2:A30,"")} -> 0 | J3: {=_xlfn.XLOOKUP("Alba Becerra",Cronograma!H2:H30,Cronograma!A2:A30,"")} -> 0 | K3: {=_xlfn.XLOOKUP("Alba Becerra",Cronograma!I2:I30,Cronograma!A2:A30,"")} -> 0 | L3: {=_xlfn.XLOOKUP("Alba Becerra",Cronograma!J2:J30,Cronograma!A2:A30,"")} -> 0 | M3: {=_xlfn.XLOOKUP("Alba Becerra",Cronograma!K2:K30,Cronograma!A2:A30,"")} -> 0 | N3: {=_xlfn.XLOOKUP("Alba Becerra",Cronograma!L2:L30,Cronograma!A2:A30,"")} -> 0 | O3: {=_xlfn.XLOOKUP("Alba Becerra",Cronograma!M2:M30,Cronograma!A2:A30,"")} -> 0 | P3: {=_xlfn.XLOOKUP("Alba Becerra",Cronograma!N2:N30,Cronograma!A2:A30,"")} -> 0 | Q3: {=_xlfn.XLOOKUP("Alba Becerra",Cronograma!O2:O30,Cronograma!A2:A30,"")} -> 0 | R3: {=_xlfn.XLOOKUP("Alba Becerra",Cronograma!P2:P30,Cronograma!A2:A30,"")} -> 0 | S3: {=_xlfn.XLOOKUP("Alba Becerra",Cronograma!Q2:Q30,Cronograma!A2:A30,"")} -> 0
A4: Angie Castillo | B4: =SUMPRODUCT((Cronograma!B2:B30=FALSE) * (COUNTIF(E4:S4, Cronograma!A2:A30))) -> 0 | C4: =SUMPRODUCT((Cronograma!B2:B30=TRUE) * (COUNTIF(E4:S4, Cronograma!A2:A30))) -> 0 | D4: =SUM(((SUMPRODUCT((Cronograma!C$2:C$30=$A4)*1)=0)*NOT(SUMPRODUCT((Cronograma!D$2:D$30=$A4)*(Cronograma!$B$2:$B$30=FALSE))>0)),(((SUMPRODUCT((Cronograma!D$2:D$30=$A4)*1)=0)*NOT(SUMPRODUCT((Cronograma!C$2:C$30=$A4)*(Cronograma!$B$2:$B$30=TRUE))>0))+((SUMPRODUCT((Cronograma!D$2:D$30=$A4)*1)=0)*NOT(SUMPRODUCT((Cronograma!E$2:E$30=$A4)*(Cronograma!$B$2:$B$30=FALSE))>0))>0),(((SUMPRODUCT((Cronograma!E$2:E$30=$A4)*1)=0)*NOT(SUMPRODUCT((Cronograma!D$2:D$30=$A4)*(Cronograma!$B$2:$B$30=TRUE))>0))+((SUMPRODUCT((Cronograma!E$2:E$30=$A4)*1)=0)*NOT(SUMPRODUCT((Cronograma!F$2:F$30=$A4)*(Cronograma!$B$2:$B$30=FALSE))>0))>0),(((SUMPRODUCT((Cronograma!F$2:F$30=$A4)*1)=0)*NOT(SUMPRODUCT((Cronograma!E$2:E$30=$A4)*(Cronograma!$B$2:$B$30=TRUE))>0))+((SUMPRODUCT((Cronograma!F$2:F$30=$A4)*1)=0)*NOT(SUMPRODUCT((Cronograma!G$2:G$30=$A4)*(Cronograma!$B$2:$B$30=FALSE))>0))>0),(((SUMPRODUCT((Cronograma!G$2:G$30=$A4)*1)=0)*NOT(SUMPRODUCT((Cronograma!F$2:F$30=$A4)*(Cronograma!$B$2:$B$30=TRUE))>0))+((SUMPRODUCT((Cronograma!G$2:G$30=$A4)*1)=0)*NOT(SUMPRODUCT((Cronograma!H$2:H$30=$A4)*(Cronograma!$B$2:$B$30=FALSE))>0))>0),(((SUMPRODUCT((Cronograma!H$2:H$30=$A4)*1)=0)*NOT(SUMPRODUCT((Cronograma!G$2:G$30=$A4)*(Cronograma!$B$2:$B$30=TRUE))>0))+((SUMPRODUCT((Cronograma!H$2:H$30=$A4)*1)=0)*NOT(SUMPRODUCT((Cronograma!I$2:I$30=$A4)*(Cronograma!$B$2:$B$30=FALSE))>0))>0),(((SUMPRODUCT((Cronograma!I$2:I$30=$A4)*1)=0)*NOT(SUMPRODUCT((Cronograma!H$2:H$30=$A4)*(Cronograma!$B$2:$B$30=TRUE))>0))+((SUMPRODUCT((Cronograma!I$2:I$30=$A4)*1)=0)*NOT(SUMPRODUCT((Cronograma!J$2:J$30=$A4)*(Cronograma!$B$2:$B$30=FALSE))>0))>0),(((SUMPRODUCT((Cronograma!J$2:J$30=$A4)*1)=0)*NOT(SUMPRODUCT((Cronograma!I$2:I$30=$A4)*(Cronograma!$B$2:$B$30=TRUE))>0))+((SUMPRODUCT((Cronograma!J$2:J$30=$A4)*1)=0)*NOT(SUMPRODUCT((Cronograma!K$2:K$30=$A4)*(Cronograma!$B$2:$B$30=FALSE))>0))>0),(((SUMPRODUCT((Cronograma!K$2:K$30=$A4)*1)=0)*NOT(SUMPRODUCT((Cronograma!J$2:J$30=$A4)*(Cronograma!$B$2:$B$30=TRUE))>0))+((SUMPRODUCT((Cronograma!K$2:K$30=$A4)*1)=0)*NOT(SUMPRODUCT((Cronograma!L$2:L$30=$A4)*(Cronograma!$B$2:$B$30=FALSE))>0))>0),(((SUMPRODUCT((Cronograma!L$2:L$30=$A4)*1)=0)*NOT(SUMPRODUCT((Cronograma!K$2:K$30=$A4)*(Cronograma!$B$2:$B$30=TRUE))>0))+((SUMPRODUCT((Cronograma!L$2:L$30=$A4)*1)=0)*NOT(SUMPRODUCT((Cronograma!M$2:M$30=$A4)*(Cronograma!$B$2:$B$30=FALSE))>0))>0),(((SUMPRODUCT((Cronograma!M$2:M$30=$A4)*1)=0)*NOT(SUMPRODUCT((Cronograma!L$2:L$30=$A4)*(Cronograma!$B$2:$B$30=TRUE))>0))+((SUMPRODUCT((Cronograma!M$2:M$30=$A4)*1)=0)*NOT(SUMPRODUCT((Cronograma!N$2:N$30=$A4)*(Cronograma!$B$2:$B$30=FALSE))>0))>0),(((SUMPRODUCT((Cronograma!N$2:N$30=$A4)*1)=0)*NOT(SUMPRODUCT((Cronograma!M$2:M$30=$A4)*(Cronograma!$B$2:$B$30=TRUE))>0))+((SUMPRODUCT((Cronograma!N$2:N$30=$A4)*1)=0)*NOT(SUMPRODUCT((Cronograma!O$2:O$30=$A4)*(Cronograma!$B$2:$B$30=FALSE))>0))>0),(((SUMPRODUCT((Cronograma!O$2:O$30=$A4)*1)=0)*NOT(SUMPRODUCT((Cronograma!N$2:N$30=$A4)*(Cronograma!$B$2:$B$30=TRUE))>0))+((SUMPRODUCT((Cronograma!O$2:O$30=$A4)*1)=0)*NOT(SUMPRODUCT((Cronograma!P$2:P$30=$A4)*(Cronograma!$B$2:$B$30=FALSE))>0))>0),(((SUMPRODUCT((Cronograma!P$2:P$30=$A4)*1)=0)*NOT(SUMPRODUCT((Cronograma!O$2:O$30=$A4)*(Cronograma!$B$2:$B$30=TRUE))>0))+((SUMPRODUCT((Cronograma!P$2:P$30=$A4)*1)=0)*NOT(SUMPRODUCT((Cronograma!Q$2:Q$30=$A4)*(Cronograma!$B$2:$B$30=FALSE))>0))>0),((SUMPRODUCT((Cronograma!Q$2:Q$30=$A4)*1)=0)*NOT(SUMPRODUCT((Cronograma!P$2:P$30=$A4)*(Cronograma!$B$2:$B$30=TRUE))>0))) -> 0 | E4: {=_xlfn.XLOOKUP("Angie Castillo",Cronograma!C2:C30,Cronograma!A2:A30,"")} -> 0 | F4: {=_xlfn.XLOOKUP("Angie Castillo",Cronograma!D2:D30,Cronograma!A2:A30,"")} -> 0 | G4: {=_xlfn.XLOOKUP("Angie Castillo",Cronograma!E2:E30,Cronograma!A2:A30,"")} -> 0 | H4: {=_xlfn.XLOOKUP("Angie Castillo",Cronograma!F2:F30,Cronograma!A2:A30,"")} -> 0 | I4: {=_xlfn.XLOOKUP("Angie Castillo",Cronograma!G2:G30,Cronograma!A2:A30,"")} -> 0 | J4: {=_xlfn.XLOOKUP("Angie Castillo",Cronograma!H2:H30,Cronograma!A2:A30,"")} -> 0 | K4: {=_xlfn.XLOOKUP("Angie Castillo",Cronograma!I2:I30,Cronograma!A2:A30,"")} -> 0 | L4: {=_xlfn.XLOOKUP("Angie Castillo",Cronograma!J2:J30,Cronograma!A2:A30,"")} -> 0 | M4: {=_xlfn.XLOOKUP("Angie Castillo",Cronograma!K2:K30,Cronograma!A2:A30,"")} -> 0 | N4: {=_xlfn.XLOOKUP("Angie Castillo",Cronograma!L2:L30,Cronograma!A2:A30,"")} -> 0 | O4: {=_xlfn.XLOOKUP("Angie Castillo",Cronograma!M2:M30,Cronograma!A2:A30,"")} -> 0 | P4: {=_xlfn.XLOOKUP("Angie Castillo",Cronograma!N2:N30,Cronograma!A2:A30,"")} -> 0 | Q4: {=_xlfn.XLOOKUP("Angie Castillo",Cronograma!O2:O30,Cronograma!A2:A30,"")} -> 0 | R4: {=_xlfn.XLOOKUP("Angie Castillo",Cronograma!P2:P30,Cronograma!A2:A30,"")} -> 0 | S4: {=_xlfn.XLOOKUP("Angie Castillo",Cronograma!Q2:Q30,Cronograma!A2:A30,"")} -> 0
A5: Anyelis | B5: =SUMPRODUCT((Cronograma!B2:B30=FALSE) * (COUNTIF(E5:S5, Cronograma!A2:A30))) -> 0 | C5: =SUMPRODUCT((Cronograma!B2:B30=TRUE) * (COUNTIF(E5:S5, Cronograma!A2:A30))) -> 0 | D5: =SUM(((SUMPRODUCT((Cronograma!C$2:C$30=$A5)*1)=0)*NOT(SUMPRODUCT((Cronograma!D$2:D$30=$A5)*(Cronograma!$B$2:$B$30=FALSE))>0)),(((SUMPRODUCT((Cronograma!D$2:D$30=$A5)*1)=0)*NOT(SUMPRODUCT((Cronograma!C$2:C$30=$A5)*(Cronograma!$B$2:$B$30=TRUE))>0))+((SUMPRODUCT((Cronograma!D$2:D$30=$A5)*1)=0)*NOT(SUMPRODUCT((Cronograma!E$2:E$30=$A5)*(Cronograma!$B$2:$B$30=FALSE))>0))>0),(((SUMPRODUCT((Cronograma!E$2:E$30=$A5)*1)=0)*NOT(SUMPRODUCT((Cronograma!D$2:D$30=$A5)*(Cronograma!$B$2:$B$30=TRUE))>0))+((SUMPRODUCT((Cronograma!E$2:E$30=$A5)*1)=0)*NOT(SUMPRODUCT((Cronograma!F$2:F$30=$A5)*(Cronograma!$B$2:$B$30=FALSE))>0))>0),(((SUMPRODUCT((Cronograma!F$2:F$30=$A5)*1)=0)*NOT(SUMPRODUCT((Cronograma!E$2:E$30=$A5)*(Cronograma!$B$2:$B$30=TRUE))>0))+((SUMPRODUCT((Cronograma!F$2:F$30=$A5)*1)=0)*NOT(SUMPRODUCT((Cronograma!G$2:G$30=$A5)*(Cronograma!$B$2:$B$30=FALSE))>0))>0),(((SUMPRODUCT((Cronograma!G$2:G$30=$A5)*1)=0)*NOT(SUMPRODUCT((Cronograma!F$2:F$30=$A5)*(Cronograma!$B$2:$B$30=TRUE))>0))+((SUMPRODUCT((Cronograma!G$2:G$30=$A5)*1)=0)*NOT(SUMPRODUCT((Cronograma!H$2:H$30=$A5)*(Cronograma!$B$2:$B$30=FALSE))>0))>0),(((SUMPRODUCT((Cronograma!H$2:H$30=$A5)*1)=0)*NOT(SUMPRODUCT((Cronograma!G$2:G$30=$A5)*(Cronograma!$B$2:$B$30=TRUE))>0))+((SUMPRODUCT((Cronograma!H$2:H$30=$A5)*1)=0)*NOT(SUMPRODUCT((Cronograma!I$2:I$30=$A5)*(Cronograma!$B$2:$B$30=FALSE))>0))>0),(((SUMPRODUCT((Cronograma!I$2:I$30=$A5)*1)=0)*NOT(SUMPRODUCT((Cronograma!H$2:H$30=$A5)*(Cronograma!$B$2:$B$30=TRUE))>0))+((SUMPRODUCT((Cronograma!I$2:I$30=$A5)*1)=0)*NOT(SUMPRODUCT((Cronograma!J$2:J$30=$A5)*(Cronograma!$B$2:$B$30=FALSE))>0))>0),(((SUMPRODUCT((Cronograma!J$2:J$30=$A5)*1)=0)*NOT(SUMPRODUCT((Cronograma!I$2:I$30=$A5)*(Cronograma!$B$2:$B$30=TRUE))>0))+((SUMPRODUCT((Cronograma!J$2:J$30=$A5)*1)=0)*NOT(SUMPRODUCT((Cronograma!K$2:K$30=$A5)*(Cronograma!$B$2:$B$30=FALSE))>0))>0),(((SUMPRODUCT((Cronograma!K$2:K$30=$A5)*1)=0)*NOT(SUMPRODUCT((Cronograma!J$2:J$30=$A5)*(Cronograma!$B$2:$B$30=TRUE))>0))+((SUMPRODUCT((Cronograma!K$2:K$30=$A5)*1)=0)*NOT(SUMPRODUCT((Cronograma!L$2:L$30=$A5)*(Cronograma!$B$2:$B$30=FALSE))>0))>0),(((SUMPRODUCT((Cronograma!L$2:L$30=$A5)*1)=0)*NOT(SUMPRODUCT((Cronograma!K$2:K$30=$A5)*(Cronograma!$B$2:$B$30=TRUE))>0))+((SUMPRODUCT((Cronograma!L$2:L$30=$A5)*1)=0)*NOT(SUMPRODUCT((Cronograma!M$2:M$30=$A5)*(Cronograma!$B$2:$B$30=FALSE))>0))>0),(((SUMPRODUCT((Cronograma!M$2:M$30=$A5)*1)=0)*NOT(SUMPRODUCT((Cronograma!L$2:L$30=$A5)*(Cronograma!$B$2:$B$30=TRUE))>0))+((SUMPRODUCT((Cronograma!M$2:M$30=$A5)*1)=0)*NOT(SUMPRODUCT((Cronograma!N$2:N$30=$A5)*(Cronograma!$B$2:$B$30=FALSE))>0))>0),(((SUMPRODUCT((Cronograma!N$2:N$30=$A5)*1)=0)*NOT(SUMPRODUCT((Cronograma!M$2:M$30=$A5)*(Cronograma!$B$2:$B$30=TRUE))>0))+((SUMPRODUCT((Cronograma!N$2:N$30=$A5)*1)=0)*NOT(SUMPRODUCT((Cronograma!O$2:O$30=$A5)*(Cronograma!$B$2:$B$30=FALSE))>0))>0),(((SUMPRODUCT((Cronograma!O$2:O$30=$A5)*1)=0)*NOT(SUMPRODUCT((Cronograma!N$2:N$30=$A5)*(Cronograma!$B$2:$B$30=TRUE))>0))+((SUMPRODUCT((Cronograma!O$2:O$30=$A5)*1)=0)*NOT(SUMPRODUCT((Cronograma!P$2:P$30=$A5)*(Cronograma!$B$2:$B$30=FALSE))>0))>0),(((SUMPRODUCT((Cronograma!P$2:P$30=$A5)*1)=0)*NOT(SUMPRODUCT((Cronograma!O$2:O$30=$A5)*(Cronograma!$B$2:$B$30=TRUE))>0))+((SUMPRODUCT((Cronograma!P$2:P$30=$A5)*1)=0)*NOT(SUMPRODUCT((Cronograma!Q$2:Q$30=$A5)*(Cronograma!$B$2:$B$30=FALSE))>0))>0),((SUMPRODUCT((Cronograma!Q$2:Q$30=$A5)*1)=0)*NOT(SUMPRODUCT((Cronograma!P$2:P$30=$A5)*(Cronograma!$B$2:$B$30=TRUE))>0))) -> 0 | E5: {=_xlfn.XLOOKUP("Anyelis",Cronograma!C2:C30,Cronograma!A2:A30,"")} -> 0 | F5: {=_xlfn.XLOOKUP("Anyelis",Cronograma!D2:D30,Cronograma!A2:A30,"")} -> 0 | G5: {=_xlfn.XLOOKUP("Anyelis",Cronograma!E2:E30,Cronograma!A2:A30,"")} -> 0 | H5: {=_xlfn.XLOOKUP("Anyelis",Cronograma!F2:F30,Cronograma!A2:A30,"")} -> 0 | I5: {=_xlfn.XLOOKUP("Anyelis",Cronograma!G2:G30,Cronograma!A2:A30,"")} -> 0 | J5: {=_xlfn.XLOOKUP("Anyelis",Cronograma!H2:H30,Cronograma!A2:A30,"")} -> 0 | K5: {=_xlfn.XLOOKUP("Anyelis",Cronograma!I2:I30,Cronograma!A2:A30,"")} -> 0 | L5: {=_xlfn.XLOOKUP("Anyelis",Cronograma!J2:J30,Cronograma!A2:A30,"")} -> 0 | M5: {=_xlfn.XLOOKUP("Anyelis",Cronograma!K2:K30,Cronograma!A2:A30,"")} -> 0 | N5: {=_xlfn.XLOOKUP("Anyelis",Cronograma!L2:L30,Cronograma!A2:A30,"")} -> 0 | O5: {=_xlfn.XLOOKUP("Anyelis",Cronograma!M2:M30,Cronograma!A2:A30,"")} -> 0 | P5: {=_xlfn.XLOOKUP("Anyelis",Cronograma!N2:N30,Cronograma!A2:A30,"")} -> 0 | Q5: {=_xlfn.XLOOKUP("Anyelis",Cronograma!O2:O30,Cronograma!A2:A30,"")} -> 0 | R5: {=_xlfn.XLOOKUP("Anyelis",Cronograma!P2:P30,Cronograma!A2:A30,"")} -> 0 | S5: {=_xlfn.XLOOKUP("Anyelis",Cronograma!Q2:Q30,Cronograma!A2:A30,"")} -> 0
A6: Darcy Lorena | B6: =SUMPRODUCT((Cronograma!B2:B30=FALSE) * (COUNTIF(E6:S6, Cronograma!A2:A30))) -> 0 | C6: =SUMPRODUCT((Cronograma!B2:B30=TRUE) * (COUNTIF(E6:S6, Cronograma!A2:A30))) -> 0 | D6: =SUM(((SUMPRODUCT((Cronograma!C$2:C$30=$A6)*1)=0)*NOT(SUMPRODUCT((Cronograma!D$2:D$30=$A6)*(Cronograma!$B$2:$B$30=FALSE))>0)),(((SUMPRODUCT((Cronograma!D$2:D$30=$A6)*1)=0)*NOT(SUMPRODUCT((Cronograma!C$2:C$30=$A6)*(Cronograma!$B$2:$B$30=TRUE))>0))+((SUMPRODUCT((Cronograma!D$2:D$30=$A6)*1)=0)*NOT(SUMPRODUCT((Cronograma!E$2:E$30=$A6)*(Cronograma!$B$2:$B$30=FALSE))>0))>0),(((SUMPRODUCT((Cronograma!E$2:E$30=$A6)*1)=0)*NOT(SUMPRODUCT((Cronograma!D$2:D$30=$A6)*(Cronograma!$B$2:$B$30=TRUE))>0))+((SUMPRODUCT((Cronograma!E$2:E$30=$A6)*1)=0)*NOT(SUMPRODUCT((Cronograma!F$2:F$30=$A6)*(Cronograma!$B$2:$B$30=FALSE))>0))>0),(((SUMPRODUCT((Cronograma!F$2:F$30=$A6)*1)=0)*NOT(SUMPRODUCT((Cronograma!E$2:E$30=$A6)*(Cronograma!$B$2:$B$30=TRUE))>0))+((SUMPRODUCT((Cronograma!F$2:F$30=$A6)*1)=0)*NOT(SUMPRODUCT((Cronograma!G$2:G$30=$A6)*(Cronograma!$B$2:$B$30=FALSE))>0))>0),(((SUMPRODUCT((Cronograma!G$2:G$30=$A6)*1)=0)*NOT(SUMPRODUCT((Cronograma!F$2:F$30=$A6)*(Cronograma!$B$2:$B$30=TRUE))>0))+((SUMPRODUCT((Cronograma!G$2:G$30=$A6)*1)=0)*NOT(SUMPRODUCT((Cronograma!H$2:H$30=$A6)*(Cronograma!$B$2:$B$30=FALSE))>0))>0),(((SUMPRODUCT((Cronograma!H$2:H$30=$A6)*1)=0)*NOT(SUMPRODUCT((Cronograma!G$2:G$30=$A6)*(Cronograma!$B$2:$B$30=TRUE))>0))+((SUMPRODUCT((Cronograma!H$2:H$30=$A6)*1)=0)*NOT(SUMPRODUCT((Cronograma!I$2:I$30=$A6)*(Cronograma!$B$2:$B$30=FALSE))>0))>0),(((SUMPRODUCT((Cronograma!I$2:I$30=$A6)*1)=0)*NOT(SUMPRODUCT((Cronograma!H$2:H$30=$A6)*(Cronograma!$B$2:$B$30=TRUE))>0))+((SUMPRODUCT((Cronograma!I$2:I$30=$A6)*1)=0)*NOT(SUMPRODUCT((Cronograma!J$2:J$30=$A6)*(Cronograma!$B$2:$B$30=FALSE))>0))>0),(((SUMPRODUCT((Cronograma!J$2:J$30=$A6)*1)=0)*NOT(SUMPRODUCT((Cronograma!I$2:I$30=$A6)*(Cronograma!$B$2:$B$30=TRUE))>0))+((SUMPRODUCT((Cronograma!J$2:J$30=$A6)*1)=0)*NOT(SUMPRODUCT((Cronograma!K$2:K$30=$A6)*(Cronograma!$B$2:$B$30=FALSE))>0))>0),(((SUMPRODUCT((Cronograma!K$2:K$30=$A6)*1)=0)*NOT(SUMPRODUCT((Cronograma!J$2:J$30=$A6)*(Cronograma!$B$2:$B$30=TRUE))>0))+((SUMPRODUCT((Cronograma!K$2:K$30=$A6)*1)=0)*NOT(SUMPRODUCT((Cronograma!L$2:L$30=$A6)*(Cronograma!$B$2:$B$30=FALSE))>0))>0),(((SUMPRODUCT((Cronograma!L$2:L$30=$A6)*1)=0)*NOT(SUMPRODUCT((Cronograma!K$2:K$30=$A6)*(Cronograma!$B$2:$B$30=TRUE))>0))+((SUMPRODUCT((Cronograma!L$2:L$30=$A6)*1)=0)*NOT(SUMPRODUCT((Cronograma!M$2:M$30=$A6)*(Cronograma!$B$2:$B$30=FALSE))>0))>0),(((SUMPRODUCT((Cronograma!M$2:M$30=$A6)*1)=0)*NOT(SUMPRODUCT((Cronograma!L$2:L$30=$A6)*(Cronograma!$B$2:$B$30=TRUE))>0))+((SUMPRODUCT((Cronograma!M$2:M$30=$A6)*1)=0)*NOT(SUMPRODUCT((Cronograma!N$2:N$30=$A6)*(Cronograma!$B$2:$B$30=FALSE))>0))>0),(((SUMPRODUCT((Cronograma!N$2:N$30=$A6)*1)=0)*NOT(SUMPRODUCT((Cronograma!M$2:M$30=$A6)*(Cronograma!$B$2:$B$30=TRUE))>0))+((SUMPRODUCT((Cronograma!N$2:N$30=$A6)*1)=0)*NOT(SUMPRODUCT((Cronograma!O$2:O$30=$A6)*(Cronograma!$B$2:$B$30=FALSE))>0))>0),(((SUMPRODUCT((Cronograma!O$2:O$30=$A6)*1)=0)*NOT(SUMPRODUCT((Cronograma!N$2:N$30=$A6)*(Cronograma!$B$2:$B$30=TRUE))>0))+((SUMPRODUCT((Cronograma!O$2:O$30=$A6)*1)=0)*NOT(SUMPRODUCT((Cronograma!P$2:P$30=$A6)*(Cronograma!$B$2:$B$30=FALSE))>0))>0),(((SUMPRODUCT((Cronograma!P$2:P$30=$A6)*1)=0)*NOT(SUMPRODUCT((Cronograma!O$2:O$30=$A6)*(Cronograma!$B$2:$B$30=TRUE))>0))+((SUMPRODUCT((Cronograma!P$2:P$30=$A6)*1)=0)*NOT(SUMPRODUCT((Cronograma!Q$2:Q$30=$A6)*(Cronograma!$B$2:$B$30=FALSE))>0))>0),((SUMPRODUCT((Cronograma!Q$2:Q$30=$A6)*1)=0)*NOT(SUMPRODUCT((Cronograma!P$2:P$30=$A6)*(Cronograma!$B$2:$B$30=TRUE))>0))) -> 0 | E6: {=_xlfn.XLOOKUP("Darcy Lorena",Cronograma!C2:C30,Cronograma!A2:A30,"")} -> 0 | F6: {=_xlfn.XLOOKUP("Darcy Lorena",Cronograma!D2:D30,Cronograma!A2:A30,"")} -> 0 | G6: {=_xlfn.XLOOKUP("Darcy Lorena",Cronograma!E2:E30,Cronograma!A2:A30,"")} -> 0 | H6: {=_xlfn.XLOOKUP("Darcy Lorena",Cronograma!F2:F30,Cronograma!A2:A30,"")} -> 0 | I6: {=_xlfn.XLOOKUP("Darcy Lorena",Cronograma!G2:G30,Cronograma!A2:A30,"")} -> 0 | J6: {=_xlfn.XLOOKUP("Darcy Lorena",Cronograma!H2:H30,Cronograma!A2:A30,"")} -> 0 | K6: {=_xlfn.XLOOKUP("Darcy Lorena",Cronograma!I2:I30,Cronograma!A2:A30,"")} -> 0 | L6: {=_xlfn.XLOOKUP("Darcy Lorena",Cronograma!J2:J30,Cronograma!A2:A30,"")} -> 0 | M6: {=_xlfn.XLOOKUP("Darcy Lorena",Cronograma!K2:K30,Cronograma!A2:A30,"")} -> 0 | N6: {=_xlfn.XLOOKUP("Darcy Lorena",Cronograma!L2:L30,Cronograma!A2:A30,"")} -> 0 | O6: {=_xlfn.XLOOKUP("Darcy Lorena",Cronograma!M2:M30,Cronograma!A2:A30,"")} -> 0 | P6: {=_xlfn.XLOOKUP("Darcy Lorena",Cronograma!N2:N30,Cronograma!A2:A30,"")} -> 0 | Q6: {=_xlfn.XLOOKUP("Darcy Lorena",Cronograma!O2:O30,Cronograma!A2:A30,"")} -> 0 | R6: {=_xlfn.XLOOKUP("Darcy Lorena",Cronograma!P2:P30,Cronograma!A2:A30,"")} -> 0 | S6: {=_xlfn.XLOOKUP("Darcy Lorena",Cronograma!Q2:Q30,Cronograma!A2:A30,"")} -> 0
A7: Diana Carolina Molina | B7: =SUMPRODUCT((Cronograma!B2:B30=FALSE) * (COUNTIF(E7:S7, Cronograma!A2:A30))) -> 0 | C7: =SUMPRODUCT((Cronograma!B2:B30=TRUE) * (COUNTIF(E7:S7, Cronograma!A2:A30))) -> 0 | D7: =SUM(((SUMPRODUCT((Cronograma!C$2:C$30=$A7)*1)=0)*NOT(SUMPRODUCT((Cronograma!D$2:D$30=$A7)*(Cronograma!$B$2:$B$30=FALSE))>0)),(((SUMPRODUCT((Cronograma!D$2:D$30=$A7)*1)=0)*NOT(SUMPRODUCT((Cronograma!C$2:C$30=$A7)*(Cronograma!$B$2:$B$30=TRUE))>0))+((SUMPRODUCT((Cronograma!D$2:D$30=$A7)*1)=0)*NOT(SUMPRODUCT((Cronograma!E$2:E$30=$A7)*(Cronograma!$B$2:$B$30=FALSE))>0))>0),(((SUMPRODUCT((Cronograma!E$2:E$30=$A7)*1)=0)*NOT(SUMPRODUCT((Cronograma!D$2:D$30=$A7)*(Cronograma!$B$2:$B$30=TRUE))>0))+((SUMPRODUCT((Cronograma!E$2:E$30=$A7)*1)=0)*NOT(SUMPRODUCT((Cronograma!F$2:F$30=$A7)*(Cronograma!$B$2:$B$30=FALSE))>0))>0),(((SUMPRODUCT((Cronograma!F$2:F$30=$A7)*1)=0)*NOT(SUMPRODUCT((Cronograma!E$2:E$30=$A7)*(Cronograma!$B$2:$B$30=TRUE))>0))+((SUMPRODUCT((Cronograma!F$2:F$30=$A7)*1)=0)*NOT(SUMPRODUCT((Cronograma!G$2:G$30=$A7)*(Cronograma!$B$2:$B$30=FALSE))>0))>0),(((SUMPRODUCT((Cronograma!G$2:G$30=$A7)*1)=0)*NOT(SUMPRODUCT((Cronograma!F$2:F$30=$A7)*(Cronograma!$B$2:$B$30=TRUE))>0))+((SUMPRODUCT((Cronograma!G$2:G$30=$A7)*1)=0)*NOT(SUMPRODUCT((Cronograma!H$2:H$30=$A7)*(Cronograma!$B$2:$B$30=FALSE))>0))>0),(((SUMPRODUCT((Cronograma!H$2:H$30=$A7)*1)=0)*NOT(SUMPRODUCT((Cronograma!G$2:G$30=$A7)*(Cronograma!$B$2:$B$30=TRUE))>0))+((SUMPRODUCT((Cronograma!H$2:H$30=$A7)*1)=0)*NOT(SUMPRODUCT((Cronograma!I$2:I$30=$A7)*(Cronograma!$B$2:$B$30=FALSE))>0))>0),(((SUMPRODUCT((Cronograma!I$2:I$30=$A7)*1)=0)*NOT(SUMPRODUCT((Cronograma!H$2:H$30=$A7)*(Cronograma!$B$2:$B$30=TRUE))>0))+((SUMPRODUCT((Cronograma!I$2:I$30=$A7)*1)=0)*NOT(SUMPRODUCT((Cronograma!J$2:J$30=$A7)*(Cronograma!$B$2:$B$30=FALSE))>0))>0),(((SUMPRODUCT((Cronograma!J$2:J$30=$A7)*1)=0)*NOT(SUMPRODUCT((Cronograma!I$2:I$30=$A7)*(Cronograma!$B$2:$B$30=TRUE))>0))+((SUMPRODUCT((Cronograma!J$2:J$30=$A7)*1)=0)*NOT(SUMPRODUCT((Cronograma!K$2:K$30=$A7)*(Cronograma!$B$2:$B$30=FALSE))>0))>0),(((SUMPRODUCT((Cronograma!K$2:K$30=$A7)*1)=0)*NOT(SUMPRODUCT((Cronograma!J$2:J$30=$A7)*(Cronograma!$B$2:$B$30=TRUE))>0))+((SUMPRODUCT((Cronograma!K$2:K$30=$A7)*1)=0)*NOT(SUMPRODUCT((Cronograma!L$2:L$30=$A7)*(Cronograma!$B$2:$B$30=FALSE))>0))>0),(((SUMPRODUCT((Cronograma!L$2:L$30=$A7)*1)=0)*NOT(SUMPRODUCT((Cronograma!K$2:K$30=$A7)*(Cronograma!$B$2:$B$30=TRUE))>0))+((SUMPRODUCT((Cronograma!L$2:L$30=$A7)*1)=0)*NOT(SUMPRODUCT((Cronograma!M$2:M$30=$A7)*(Cronograma!$B$2:$B$30=FALSE))>0))>0),(((SUMPRODUCT((Cronograma!M$2:M$30=$A7)*1)=0)*NOT(SUMPRODUCT((Cronograma!L$2:L$30=$A7)*(Cronograma!$B$2:$B$30=TRUE))>0))+((SUMPRODUCT((Cronograma!M$2:M$30=$A7)*1)=0)*NOT(SUMPRODUCT((Cronograma!N$2:N$30=$A7)*(Cronograma!$B$2:$B$30=FALSE))>0))>0),(((SUMPRODUCT((Cronograma!N$2:N$30=$A7)*1)=0)*NOT(SUMPRODUCT((Cronograma!M$2:M$30=$A7)*(Cronograma!$B$2:$B$30=TRUE))>0))+((SUMPRODUCT((Cronograma!N$2:N$30=$A7)*1)=0)*NOT(SUMPRODUCT((Cronograma!O$2:O$30=$A7)*(Cronograma!$B$2:$B$30=FALSE))>0))>0),(((SUMPRODUCT((Cronograma!O$2:O$30=$A7)*1)=0)*NOT(SUMPRODUCT((Cronograma!N$2:N$30=$A7)*(Cronograma!$B$2:$B$30=TRUE))>0))+((SUMPRODUCT((Cronograma!O$2:O$30=$A7)*1)=0)*NOT(SUMPRODUCT((Cronograma!P$2:P$30=$A7)*(Cronograma!$B$2:$B$30=FALSE))>0))>0),(((SUMPRODUCT((Cronograma!P$2:P$30=$A7)*1)=0)*NOT(SUMPRODUCT((Cronograma!O$2:O$30=$A7)*(Cronograma!$B$2:$B$30=TRUE))>0))+((SUMPRODUCT((Cronograma!P$2:P$30=$A7)*1)=0)*NOT(SUMPRODUCT((Cronograma!Q$2:Q$30=$A7)*(Cronograma!$B$2:$B$30=FALSE))>0))>0),((SUMPRODUCT((Cronograma!Q$2:Q$30=$A7)*1)=0)*NOT(SUMPRODUCT((Cronograma!P$2:P$30=$A7)*(Cronograma!$B$2:$B$30=TRUE))>0))) -> 0 | E7: {=_xlfn.XLOOKUP("Diana Carolina Molina",Cronograma!C2:C30,Cronograma!A2:A30,"")} -> 0 | F7: {=_xlfn.XLOOKUP("Diana Carolina Molina",Cronograma!D2:D30,Cronograma!A2:A30,"")} -> 0 | G7: {=_xlfn.XLOOKUP("Diana Carolina Molina",Cronograma!E2:E30,Cronograma!A2:A30,"")} -> 0 | H7: {=_xlfn.XLOOKUP("Diana Carolina Molina",Cronograma!F2:F30,Cronograma!A2:A30,"")} -> 0 | I7: {=_xlfn.XLOOKUP("Diana Carolina Molina",Cronograma!G2:G30,Cronograma!A2:A30,"")} -> 0 | J7: {=_xlfn.XLOOKUP("Diana Carolina Molina",Cronograma!H2:H30,Cronograma!A2:A30,"")} -> 0 | K7: {=_xlfn.XLOOKUP("Diana Carolina Molina",Cronograma!I2:I30,Cronograma!A2:A30,"")} -> 0 | L7: {=_xlfn.XLOOKUP("Diana Carolina Molina",Cronograma!J2:J30,Cronograma!A2:A30,"")} -> 0 | M7: {=_xlfn.XLOOKUP("Diana Carolina Molina",Cronograma!K2:K30,Cronograma!A2:A30,"")} -> 0 | N7: {=_xlfn.XLOOKUP("Diana Carolina Molina",Cronograma!L2:L30,Cronograma!A2:A30,"")} -> 0 | O7: {=_xlfn.XLOOKUP("Diana Carolina Molina",Cronograma!M2:M30,Cronograma!A2:A30,"")} -> 0 | P7: {=_xlfn.XLOOKUP("Diana Carolina Molina",Cronograma!N2:N30,Cronograma!A2:A30,"")} -> 0 | Q7: {=_xlfn.XLOOKUP("Diana Carolina Molina",Cronograma!O2:O30,Cronograma!A2:A30,"")} -> 0 | R7: {=_xlfn.XLOOKUP("Diana Carolina Molina",Cronograma!P2:P30,Cronograma!A2:A30,"")} -> 0 | S7: {=_xlfn.XLOOKUP("Diana Carolina Molina",Cronograma!Q2:Q30,Cronograma!A2:A30,"")} -> 0
A8: Efigenia | B8: =SUMPRODUCT((Cronograma!B2:B30=FALSE) * (COUNTIF(E8:S8, Cronograma!A2:A30))) -> 0 | C8: =SUMPRODUCT((Cronograma!B2:B30=TRUE) * (COUNTIF(E8:S8, Cronograma!A2:A30))) -> 0 | D8: =SUM(((SUMPRODUCT((Cronograma!C$2:C$30=$A8)*1)=0)*NOT(SUMPRODUCT((Cronograma!D$2:D$30=$A8)*(Cronograma!$B$2:$B$30=FALSE))>0)),(((SUMPRODUCT((Cronograma!D$2:D$30=$A8)*1)=0)*NOT(SUMPRODUCT((Cronograma!C$2:C$30=$A8)*(Cronograma!$B$2:$B$30=TRUE))>0))+((SUMPRODUCT((Cronograma!D$2:D$30=$A8)*1)=0)*NOT(SUMPRODUCT((Cronograma!E$2:E$30=$A8)*(Cronograma!$B$2:$B$30=FALSE))>0))>0),(((SUMPRODUCT((Cronograma!E$2:E$30=$A8)*1)=0)*NOT(SUMPRODUCT((Cronograma!D$2:D$30=$A8)*(Cronograma!$B$2:$B$30=TRUE))>0))+((SUMPRODUCT((Cronograma!E$2:E$30=$A8)*1)=0)*NOT(SUMPRODUCT((Cronograma!F$2:F$30=$A8)*(Cronograma!$B$2:$B$30=FALSE))>0))>0),(((SUMPRODUCT((Cronograma!F$2:F$30=$A8)*1)=0)*NOT(SUMPRODUCT((Cronograma!E$2:E$30=$A8)*(Cronograma!$B$2:$B$30=TRUE))>0))+((SUMPRODUCT((Cronograma!F$2:F$30=$A8)*1)=0)*NOT(SUMPRODUCT((Cronograma!G$2:G$30=$A8)*(Cronograma!$B$2:$B$30=FALSE))>0))>0),(((SUMPRODUCT((Cronograma!G$2:G$30=$A8)*1)=0)*NOT(SUMPRODUCT((Cronograma!F$2:F$30=$A8)*(Cronograma!$B$2:$B$30=TRUE))>0))+((SUMPRODUCT((Cronograma!G$2:G$30=$A8)*1)=0)*NOT(SUMPRODUCT((Cronograma!H$2:H$30=$A8)*(Cronograma!$B$2:$B$30=FALSE))>0))>0),(((SUMPRODUCT((Cronograma!H$2:H$30=$A8)*1)=0)*NOT(SUMPRODUCT((Cronograma!G$2:G$30=$A8)*(Cronograma!$B$2:$B$30=TRUE))>0))+((SUMPRODUCT((Cronograma!H$2:H$30=$A8)*1)=0)*NOT(SUMPRODUCT((Cronograma!I$2:I$30=$A8)*(Cronograma!$B$2:$B$30=FALSE))>0))>0),(((SUMPRODUCT((Cronograma!I$2:I$30=$A8)*1)=0)*NOT(SUMPRODUCT((Cronograma!H$2:H$30=$A8)*(Cronograma!$B$2:$B$30=TRUE))>0))+((SUMPRODUCT((Cronograma!I$2:I$30=$A8)*1)=0)*NOT(SUMPRODUCT((Cronograma!J$2:J$30=$A8)*(Cronograma!$B$2:$B$30=FALSE))>0))>0),(((SUMPRODUCT((Cronograma!J$2:J$30=$A8)*1)=0)*NOT(SUMPRODUCT((Cronograma!I$2:I$30=$A8)*(Cronograma!$B$2:$B$30=TRUE))>0))+((SUMPRODUCT((Cronograma!J$2:J$30=$A8)*1)=0)*NOT(SUMPRODUCT((Cronograma!K$2:K$30=$A8)*(Cronograma!$B$2:$B$30=FALSE))>0))>0),(((SUMPRODUCT((Cronograma!K$2:K$30=$A8)*1)=0)*NOT(SUMPRODUCT((Cronograma!J$2:J$30=$A8)*(Cronograma!$B$2:$B$30=TRUE))>0))+((SUMPRODUCT((Cronograma!K$2:K$30=$A8)*1)=0)*NOT(SUMPRODUCT((Cronograma!L$2:L$30=$A8)*(Cronograma!$B$2:$B$30=FALSE))>0))>0),(((SUMPRODUCT((Cronograma!L$2:L$30=$A8)*1)=0)*NOT(SUMPRODUCT((Cronograma!K$2:K$30=$A8)*(Cronograma!$B$2:$B$30=TRUE))>0))+((SUMPRODUCT((Cronograma!L$2:L$30=$A8)*1)=0)*NOT(SUMPRODUCT((Cronograma!M$2:M$30=$A8)*(Cronograma!$B$2:$B$30=FALSE))>0))>0),(((SUMPRODUCT((Cronograma!M$2:M$30=$A8)*1)=0)*NOT(SUMPRODUCT((Cronograma!L$2:L$30=$A8)*(Cronograma!$B$2:$B$30=TRUE))>0))+((SUMPRODUCT((Cronograma!M$2:M$30=$A8)*1)=0)*NOT(SUMPRODUCT((Cronograma!N$2:N$30=$A8)*(Cronograma!$B$2:$B$30=FALSE))>0))>0),(((SUMPRODUCT((Cronograma!N$2:N$30=$A8)*1)=0)*NOT(SUMPRODUCT((Cronograma!M$2:M$30=$A8)*(Cronograma!$B$2:$B$30=TRUE))>0))+((SUMPRODUCT((Cronograma!N$2:N$30=$A8)*1)=0)*NOT(SUMPRODUCT((Cronograma!O$2:O$30=$A8)*(Cronograma!$B$2:$B$30=FALSE))>0))>0),(((SUMPRODUCT((Cronograma!O$2:O$30=$A8)*1)=0)*NOT(SUMPRODUCT((Cronograma!N$2:N$30=$A8)*(Cronograma!$B$2:$B$30=TRUE))>0))+((SUMPRODUCT((Cronograma!O$2:O$30=$A8)*1)=0)*NOT(SUMPRODUCT((Cronograma!P$2:P$30=$A8)*(Cronograma!$B$2:$B$30=FALSE))>0))>0),(((SUMPRODUCT((Cronograma!P$2:P$30=$A8)*1)=0)*NOT(SUMPRODUCT((Cronograma!O$2:O$30=$A8)*(Cronograma!$B$2:$B$30=TRUE))>0))+((SUMPRODUCT((Cronograma!P$2:P$30=$A8)*1)=0)*NOT(SUMPRODUCT((Cronograma!Q$2:Q$30=$A8)*(Cronograma!$B$2:$B$30=FALSE))>0))>0),((SUMPRODUCT((Cronograma!Q$2:Q$30=$A8)*1)=0)*NOT(SUMPRODUCT((Cronograma!P$2:P$30=$A8)*(Cronograma!$B$2:$B$30=TRUE))>0))) -> 0 | E8: {=_xlfn.XLOOKUP("Efigenia",Cronograma!C2:C30,Cronograma!A2:A30,"")} -> 0 | F8: {=_xlfn.XLOOKUP("Efigenia",Cronograma!D2:D30,Cronograma!A2:A30,"")} -> 0 | G8: {=_xlfn.XLOOKUP("Efigenia",Cronograma!E2:E30,Cronograma!A2:A30,"")} -> 0 | H8: {=_xlfn.XLOOKUP("Efigenia",Cronograma!F2:F30,Cronograma!A2:A30,"")} -> 0 | I8: {=_xlfn.XLOOKUP("Efigenia",Cronograma!G2:G30,Cronograma!A2:A30,"")} -> 0 | J8: {=_xlfn.XLOOKUP("Efigenia",Cronograma!H2:H30,Cronograma!A2:A30,"")} -> 0 | K8: {=_xlfn.XLOOKUP("Efigenia",Cronograma!I2:I30,Cronograma!A2:A30,"")} -> 0 | L8: {=_xlfn.XLOOKUP("Efigenia",Cronograma!J2:J30,Cronograma!A2:A30,"")} -> 0 | M8: {=_xlfn.XLOOKUP("Efigenia",Cronograma!K2:K30,Cronograma!A2:A30,"")} -> 0 | N8: {=_xlfn.XLOOKUP("Efigenia",Cronograma!L2:L30,Cronograma!A2:A30,"")} -> 0 | O8: {=_xlfn.XLOOKUP("Efigenia",Cronograma!M2:M30,Cronograma!A2:A30,"")} -> 0 | P8: {=_xlfn.XLOOKUP("Efigenia",Cronograma!N2:N30,Cronograma!A2:A30,"")} -> 0 | Q8: {=_xlfn.XLOOKUP("Efigenia",Cronograma!O2:O30,Cronograma!A2:A30,"")} -> 0 | R8: {=_xlfn.XLOOKUP("Efigenia",Cronograma!P2:P30,Cronograma!A2:A30,"")} -> 0 | S8: {=_xlfn.XLOOKUP("Efigenia",Cronograma!Q2:Q30,Cronograma!A2:A30,"")} -> 0
A9: Elisa Parra | B9: =SUMPRODUCT((Cronograma!B2:B30=FALSE) * (COUNTIF(E9:S9, Cronograma!A2:A30))) -> 0 | C9: =SUMPRODUCT((Cronograma!B2:B30=TRUE) * (COUNTIF(E9:S9, Cronograma!A2:A30))) -> 0 | D9: =SUM(((SUMPRODUCT((Cronograma!C$2:C$30=$A9)*1)=0)*NOT(SUMPRODUCT((Cronograma!D$2:D$30=$A9)*(Cronograma!$B$2:$B$30=FALSE))>0)),(((SUMPRODUCT((Cronograma!D$2:D$30=$A9)*1)=0)*NOT(SUMPRODUCT((Cronograma!C$2:C$30=$A9)*(Cronograma!$B$2:$B$30=TRUE))>0))+((SUMPRODUCT((Cronograma!D$2:D$30=$A9)*1)=0)*NOT(SUMPRODUCT((Cronograma!E$2:E$30=$A9)*(Cronograma!$B$2:$B$30=FALSE))>0))>0),(((SUMPRODUCT((Cronograma!E$2:E$30=$A9)*1)=0)*NOT(SUMPRODUCT((Cronograma!D$2:D$30=$A9)*(Cronograma!$B$2:$B$30=TRUE))>0))+((SUMPRODUCT((Cronograma!E$2:E$30=$A9)*1)=0)*NOT(SUMPRODUCT((Cronograma!F$2:F$30=$A9)*(Cronograma!$B$2:$B$30=FALSE))>0))>0),(((SUMPRODUCT((Cronograma!F$2:F$30=$A9)*1)=0)*NOT(SUMPRODUCT((Cronograma!E$2:E$30=$A9)*(Cronograma!$B$2:$B$30=TRUE))>0))+((SUMPRODUCT((Cronograma!F$2:F$30=$A9)*1)=0)*NOT(SUMPRODUCT((Cronograma!G$2:G$30=$A9)*(Cronograma!$B$2:$B$30=FALSE))>0))>0),(((SUMPRODUCT((Cronograma!G$2:G$30=$A9)*1)=0)*NOT(SUMPRODUCT((Cronograma!F$2:F$30=$A9)*(Cronograma!$B$2:$B$30=TRUE))>0))+((SUMPRODUCT((Cronograma!G$2:G$30=$A9)*1)=0)*NOT(SUMPRODUCT((Cronograma!H$2:H$30=$A9)*(Cronograma!$B$2:$B$30=FALSE))>0))>0),(((SUMPRODUCT((Cronograma!H$2:H$30=$A9)*1)=0)*NOT(SUMPRODUCT((Cronograma!G$2:G$30=$A9)*(Cronograma!$B$2:$B$30=TRUE))>0))+((SUMPRODUCT((Cronograma!H$2:H$30=$A9)*1)=0)*NOT(SUMPRODUCT((Cronograma!I$2:I$30=$A9)*(Cronograma!$B$2:$B$30=FALSE))>0))>0),(((SUMPRODUCT((Cronograma!I$2:I$30=$A9)*1)=0)*NOT(SUMPRODUCT((Cronograma!H$2:H$30=$A9)*(Cronograma!$B$2:$B$30=TRUE))>0))+((SUMPRODUCT((Cronograma!I$2:I$30=$A9)*1)=0)*NOT(SUMPRODUCT((Cronograma!J$2:J$30=$A9)*(Cronograma!$B$2:$B$30=FALSE))>0))>0),(((SUMPRODUCT((Cronograma!J$2:J$30=$A9)*1)=0)*NOT(SUMPRODUCT((Cronograma!I$2:I$30=$A9)*(Cronograma!$B$2:$B$30=TRUE))>0))+((SUMPRODUCT((Cronograma!J$2:J$30=$A9)*1)=0)*NOT(SUMPRODUCT((Cronograma!K$2:K$30=$A9)*(Cronograma!$B$2:$B$30=FALSE))>0))>0),(((SUMPRODUCT((Cronograma!K$2:K$30=$A9)*1)=0)*NOT(SUMPRODUCT((Cronograma!J$2:J$30=$A9)*(Cronograma!$B$2:$B$30=TRUE))>0))+((SUMPRODUCT((Cronograma!K$2:K$30=$A9)*1)=0)*NOT(SUMPRODUCT((Cronograma!L$2:L$30=$A9)*(Cronograma!$B$2:$B$30=FALSE))>0))>0),(((SUMPRODUCT((Cronograma!L$2:L$30=$A9)*1)=0)*NOT(SUMPRODUCT((Cronograma!K$2:K$30=$A9)*(Cronograma!$B$2:$B$30=TRUE))>0))+((SUMPRODUCT((Cronograma!L$2:L$30=$A9)*1)=0)*NOT(SUMPRODUCT((Cronograma!M$2:M$30=$A9)*(Cronograma!$B$2:$B$30=FALSE))>0))>0),(((SUMPRODUCT((Cronograma!M$2:M$30=$A9)*1)=0)*NOT(SUMPRODUCT((Cronograma!L$2:L$30=$A9)*(Cronograma!$B$2:$B$30=TRUE))>0))+((SUMPRODUCT((Cronograma!M$2:M$30=$A9)*1)=0)*NOT(SUMPRODUCT((Cronograma!N$2:N$30=$A9)*(Cronograma!$B$2:$B$30=FALSE))>0))>0),(((SUMPRODUCT((Cronograma!N$2:N$30=$A9)*1)=0)*NOT(SUMPRODUCT((Cronograma!M$2:M$30=$A9)*(Cronograma!$B$2:$B$30=TRUE))>0))+((SUMPRODUCT((Cronograma!N$2:N$30=$A9)*1)=0)*NOT(SUMPRODUCT((Cronograma!O$2:O$30=$A9)*(Cronograma!$B$2:$B$30=FALSE))>0))>0),(((SUMPRODUCT((Cronograma!O$2:O$30=$A9)*1)=0)*NOT(SUMPRODUCT((Cronograma!N$2:N$30=$A9)*(Cronograma!$B$2:$B$30=TRUE))>0))+((SUMPRODUCT((Cronograma!O$2:O$30=$A9)*1)=0)*NOT(SUMPRODUCT((Cronograma!P$2:P$30=$A9)*(Cronograma!$B$2:$B$30=FALSE))>0))>0),(((SUMPRODUCT((Cronograma!P$2:P$30=$A9)*1)=0)*NOT(SUMPRODUCT((Cronograma!O$2:O$30=$A9)*(Cronograma!$B$2:$B$30=TRUE))>0))+((SUMPRODUCT((Cronograma!P$2:P$30=$A9)*1)=0)*NOT(SUMPRODUCT((Cronograma!Q$2:Q$30=$A9)*(Cronograma!$B$2:$B$30=FALSE))>0))>0),((SUMPRODUCT((Cronograma!Q$2:Q$30=$A9)*1)=0)*NOT(SUMPRODUCT((Cronograma!P$2:P$30=$A9)*(Cronograma!$B$2:$B$30=TRUE))>0))) -> 0 | E9: {=_xlfn.XLOOKUP("Elisa Parra",Cronograma!C2:C30,Cronograma!A2:A30,"")} -> 0 | F9: {=_xlfn.XLOOKUP("Elisa Parra",Cronograma!D2:D30,Cronograma!A2:A30,"")} -> 0 | G9: {=_xlfn.XLOOKUP("Elisa Parra",Cronograma!E2:E30,Cronograma!A2:A30,"")} -> 0 | H9: {=_xlfn.XLOOKUP("Elisa Parra",Cronograma!F2:F30,Cronograma!A2:A30,"")} -> 0 | I9: {=_xlfn.XLOOKUP("Elisa Parra",Cronograma!G2:G30,Cronograma!A2:A30,"")} -> 0 | J9: {=_xlfn.XLOOKUP("Elisa Parra",Cronograma!H2:H30,Cronograma!A2:A30,"")} -> 0 | K9: {=_xlfn.XLOOKUP("Elisa Parra",Cronograma!I2:I30,Cronograma!A2:A30,"")} -> 0 | L9: {=_xlfn.XLOOKUP("Elisa Parra",Cronograma!J2:J30,Cronograma!A2:A30,"")} -> 0 | M9: {=_xlfn.XLOOKUP("Elisa Parra",Cronograma!K2:K30,Cronograma!A2:A30,"")} -> 0 | N9: {=_xlfn.XLOOKUP("Elisa Parra",Cronograma!L2:L30,Cronograma!A2:A30,"")} -> 0 | O9: {=_xlfn.XLOOKUP("Elisa Parra",Cronograma!M2:M30,Cronograma!A2:A30,"")} -> 0 | P9: {=_xlfn.XLOOKUP("Elisa Parra",Cronograma!N2:N30,Cronograma!A2:A30,"")} -> 0 | Q9: {=_xlfn.XLOOKUP("Elisa Parra",Cronograma!O2:O30,Cronograma!A2:A30,"")} -> 0 | R9: {=_xlfn.XLOOKUP("Elisa Parra",Cronograma!P2:P30,Cronograma!A2:A30,"")} -> 0 | S9: {=_xlfn.XLOOKUP("Elisa Parra",Cronograma!Q2:Q30,Cronograma!A2:A30,"")} -> 0
A10: German Avila | B10: =SUMPRODUCT((Cronograma!B2:B30=FALSE) * (COUNTIF(E10:S10, Cronograma!A2:A30))) -> 0 | C10: =SUMPRODUCT((Cronograma!B2:B30=TRUE) * (COUNTIF(E10:S10, Cronograma!A2:A30))) -> 0 | D10: =SUM(((SUMPRODUCT((Cronograma!C$2:C$30=$A10)*1)=0)*NOT(SUMPRODUCT((Cronograma!D$2:D$30=$A10)*(Cronograma!$B$2:$B$30=FALSE))>0)),(((SUMPRODUCT((Cronograma!D$2:D$30=$A10)*1)=0)*NOT(SUMPRODUCT((Cronograma!C$2:C$30=$A10)*(Cronograma!$B$2:$B$30=TRUE))>0))+((SUMPRODUCT((Cronograma!D$2:D$30=$A10)*1)=0)*NOT(SUMPRODUCT((Cronograma!E$2:E$30=$A10)*(Cronograma!$B$2:$B$30=FALSE))>0))>0),(((SUMPRODUCT((Cronograma!E$2:E$30=$A10)*1)=0)*NOT(SUMPRODUCT((Cronograma!D$2:D$30=$A10)*(Cronograma!$B$2:$B$30=TRUE))>0))+((SUMPRODUCT((Cronograma!E$2:E$30=$A10)*1)=0)*NOT(SUMPRODUCT((Cronograma!F$2:F$30=$A10)*(Cronograma!$B$2:$B$30=FALSE))>0))>0),(((SUMPRODUCT((Cronograma!F$2:F$30=$A10)*1)=0)*NOT(SUMPRODUCT((Cronograma!E$2:E$30=$A10)*(Cronograma!$B$2:$B$30=TRUE))>0))+((SUMPRODUCT((Cronograma!F$2:F$30=$A10)*1)=0)*NOT(SUMPRODUCT((Cronograma!G$2:G$30=$A10)*(Cronograma!$B$2:$B$30=FALSE))>0))>0),(((SUMPRODUCT((Cronograma!G$2:G$30=$A10)*1)=0)*NOT(SUMPRODUCT((Cronograma!F$2:F$30=$A10)*(Cronograma!$B$2:$B$30=TRUE))>0))+((SUMPRODUCT((Cronograma!G$2:G$30=$A10)*1)=0)*NOT(SUMPRODUCT((Cronograma!H$2:H$30=$A10)*(Cronograma!$B$2:$B$30=FALSE))>0))>0),(((SUMPRODUCT((Cronograma!H$2:H$30=$A10)*1)=0)*NOT(SUMPRODUCT((Cronograma!G$2:G$30=$A10)*(Cronograma!$B$2:$B$30=TRUE))>0))+((SUMPRODUCT((Cronograma!H$2:H$30=$A10)*1)=0)*NOT(SUMPRODUCT((Cronograma!I$2:I$30=$A10)*(Cronograma!$B$2:$B$30=FALSE))>0))>0),(((SUMPRODUCT((Cronograma!I$2:I$30=$A10)*1)=0)*NOT(SUMPRODUCT((Cronograma!H$2:H$30=$A10)*(Cronograma!$B$2:$B$30=TRUE))>0))+((SUMPRODUCT((Cronograma!I$2:I$30=$A10)*1)=0)*NOT(SUMPRODUCT((Cronograma!J$2:J$30=$A10)*(Cronograma!$B$2:$B$30=FALSE))>0))>0),(((SUMPRODUCT((Cronograma!J$2:J$30=$A10)*1)=0)*NOT(SUMPRODUCT((Cronograma!I$2:I$30=$A10)*(Cronograma!$B$2:$B$30=TRUE))>0))+((SUMPRODUCT((Cronograma!J$2:J$30=$A10)*1)=0)*NOT(SUMPRODUCT((Cronograma!K$2:K$30=$A10)*(Cronograma!$B$2:$B$30=FALSE))>0))>0),(((SUMPRODUCT((Cronograma!K$2:K$30=$A10)*1)=0)*NOT(SUMPRODUCT((Cronograma!J$2:J$30=$A10)*(Cronograma!$B$2:$B$30=TRUE))>0))+((SUMPRODUCT((Cronograma!K$2:K$30=$A10)*1)=0)*NOT(SUMPRODUCT((Cronograma!L$2:L$30=$A10)*(Cronograma!$B$2:$B$30=FALSE))>0))>0),(((SUMPRODUCT((Cronograma!L$2:L$30=$A10)*1)=0)*NOT(SUMPRODUCT((Cronograma!K$2:K$30=$A10)*(Cronograma!$B$2:$B$30=TRUE))>0))+((SUMPRODUCT((Cronograma!L$2:L$30=$A10)*1)=0)*NOT(SUMPRODUCT((Cronograma!M$2:M$30=$A10)*(Cronograma!$B$2:$B$30=FALSE))>0))>0),(((SUMPRODUCT((Cronograma!M$2:M$30=$A10)*1)=0)*NOT(SUMPRODUCT((Cronograma!L$2:L$30=$A10)*(Cronograma!$B$2:$B$30=TRUE))>0))+((SUMPRODUCT((Cronograma!M$2:M$30=$A10)*1)=0)*NOT(SUMPRODUCT((Cronograma!N$2:N$30=$A10)*(Cronograma!$B$2:$B$30=FALSE))>0))>0),(((SUMPRODUCT((Cronograma!N$2:N$30=$A10)*1)=0)*NOT(SUMPRODUCT((Cronograma!M$2:M$30=$A10)*(Cronograma!$B$2:$B$30=TRUE))>0))+((SUMPRODUCT((Cronograma!N$2:N$30=$A10)*1)=0)*NOT(SUMPRODUCT((Cronograma!O$2:O$30=$A10)*(Cronograma!$B$2:$B$30=FALSE))>0))>0),(((SUMPRODUCT((Cronograma!O$2:O$30=$A10)*1)=0)*NOT(SUMPRODUCT((Cronograma!N$2:N$30=$A10)*(Cronograma!$B$2:$B$30=TRUE))>0))+((SUMPRODUCT((Cronograma!O$2:O$30=$A10)*1)=0)*NOT(SUMPRODUCT((Cronograma!P$2:P$30=$A10)*(Cronograma!$B$2:$B$30=FALSE))>0))>0),(((SUMPRODUCT((Cronograma!P$2:P$30=$A10)*1)=0)*NOT(SUMPRODUCT((Cronograma!O$2:O$30=$A10)*(Cronograma!$B$2:$B$30=TRUE))>0))+((SUMPRODUCT((Cronograma!P$2:P$30=$A10)*1)=0)*NOT(SUMPRODUCT((Cronograma!Q$2:Q$30=$A10)*(Cronograma!$B$2:$B$30=FALSE))>0))>0),((SUMPRODUCT((Cronograma!Q$2:Q$30=$A10)*1)=0)*NOT(SUMPRODUCT((Cronograma!P$2:P$30=$A10)*(Cronograma!$B$2:$B$30=TRUE))>0))) -> 0 | E10: {=_xlfn.XLOOKUP("German Avila",Cronograma!C2:C30,Cronograma!A2:A30,"")} -> 0 | F10: {=_xlfn.XLOOKUP("German Avila",Cronograma!D2:D30,Cronograma!A2:A30,"")} -> 0 | G10: {=_xlfn.XLOOKUP("German Avila",Cronograma!E2:E30,Cronograma!A2:A30,"")} -> 0 | H10: {=_xlfn.XLOOKUP("German Avila",Cronograma!F2:F30,Cronograma!A2:A30,"")} -> 0 | I10: {=_xlfn.XLOOKUP("German Avila",Cronograma!G2:G30,Cronograma!A2:A30,"")} -> 0 | J10: {=_xlfn.XLOOKUP("German Avila",Cronograma!H2:H30,Cronograma!A2:A30,"")} -> 0 | K10: {=_xlfn.XLOOKUP("German Avila",Cronograma!I2:I30,Cronograma!A2:A30,"")} -> 0 | L10: {=_xlfn.XLOOKUP("German Avila",Cronograma!J2:J30,Cronograma!A2:A30,"")} -> 0 | M10: {=_xlfn.XLOOKUP("German Avila",Cronograma!K2:K30,Cronograma!A2:A30,"")} -> 0 | N10: {=_xlfn.XLOOKUP("German Avila",Cronograma!L2:L30,Cronograma!A2:A30,"")} -> 0 | O10: {=_xlfn.XLOOKUP("German Avila",Cronograma!M2:M30,Cronograma!A2:A30,"")} -> 0 | P10: {=_xlfn.XLOOKUP("German Avila",Cronograma!N2:N30,Cronograma!A2:A30,"")} -> 0 | Q10: {=_xlfn.XLOOKUP("German Avila",Cronograma!O2:O30,Cronograma!A2:A30,"")} -> 0 | R10: {=_xlfn.XLOOKUP("German Avila",Cronograma!P2:P30,Cronograma!A2:A30,"")} -> 0 | S10: {=_xlfn.XLOOKUP("German Avila",Cronograma!Q2:Q30,Cronograma!A2:A30,"")} -> 0
A11: Gisela | B11: =SUMPRODUCT((Cronograma!B2:B30=FALSE) * (COUNTIF(E11:S11, Cronograma!A2:A30))) -> 0 | C11: =SUMPRODUCT((Cronograma!B2:B30=TRUE) * (COUNTIF(E11:S11, Cronograma!A2:A30))) -> 0 | D11: =SUM(((SUMPRODUCT((Cronograma!C$2:C$30=$A11)*1)=0)*NOT(SUMPRODUCT((Cronograma!D$2:D$30=$A11)*(Cronograma!$B$2:$B$30=FALSE))>0)),(((SUMPRODUCT((Cronograma!D$2:D$30=$A11)*1)=0)*NOT(SUMPRODUCT((Cronograma!C$2:C$30=$A11)*(Cronograma!$B$2:$B$30=TRUE))>0))+((SUMPRODUCT((Cronograma!D$2:D$30=$A11)*1)=0)*NOT(SUMPRODUCT((Cronograma!E$2:E$30=$A11)*(Cronograma!$B$2:$B$30=FALSE))>0))>0),(((SUMPRODUCT((Cronograma!E$2:E$30=$A11)*1)=0)*NOT(SUMPRODUCT((Cronograma!D$2:D$30=$A11)*(Cronograma!$B$2:$B$30=TRUE))>0))+((SUMPRODUCT((Cronograma!E$2:E$30=$A11)*1)=0)*NOT(SUMPRODUCT((Cronograma!F$2:F$30=$A11)*(Cronograma!$B$2:$B$30=FALSE))>0))>0),(((SUMPRODUCT((Cronograma!F$2:F$30=$A11)*1)=0)*NOT(SUMPRODUCT((Cronograma!E$2:E$30=$A11)*(Cronograma!$B$2:$B$30=TRUE))>0))+((SUMPRODUCT((Cronograma!F$2:F$30=$A11)*1)=0)*NOT(SUMPRODUCT((Cronograma!G$2:G$30=$A11)*(Cronograma!$B$2:$B$30=FALSE))>0))>0),(((SUMPRODUCT((Cronograma!G$2:G$30=$A11)*1)=0)*NOT(SUMPRODUCT((Cronograma!F$2:F$30=$A11)*(Cronograma!$B$2:$B$30=TRUE))>0))+((SUMPRODUCT((Cronograma!G$2:G$30=$A11)*1)=0)*NOT(SUMPRODUCT((Cronograma!H$2:H$30=$A11)*(Cronograma!$B$2:$B$30=FALSE))>0))>0),(((SUMPRODUCT((Cronograma!H$2:H$30=$A11)*1)=0)*NOT(SUMPRODUCT((Cronograma!G$2:G$30=$A11)*(Cronograma!$B$2:$B$30=TRUE))>0))+((SUMPRODUCT((Cronograma!H$2:H$30=$A11)*1)=0)*NOT(SUMPRODUCT((Cronograma!I$2:I$30=$A11)*(Cronograma!$B$2:$B$30=FALSE))>0))>0),(((SUMPRODUCT((Cronograma!I$2:I$30=$A11)*1)=0)*NOT(SUMPRODUCT((Cronograma!H$2:H$30=$A11)*(Cronograma!$B$2:$B$30=TRUE))>0))+((SUMPRODUCT((Cronograma!I$2:I$30=$A11)*1)=0)*NOT(SUMPRODUCT((Cronograma!J$2:J$30=$A11)*(Cronograma!$B$2:$B$30=FALSE))>0))>0),(((SUMPRODUCT((Cronograma!J$2:J$30=$A11)*1)=0)*NOT(SUMPRODUCT((Cronograma!I$2:I$30=$A11)*(Cronograma!$B$2:$B$30=TRUE))>0))+((SUMPRODUCT((Cronograma!J$2:J$30=$A11)*1)=0)*NOT(SUMPRODUCT((Cronograma!K$2:K$30=$A11)*(Cronograma!$B$2:$B$30=FALSE))>0))>0),(((SUMPRODUCT((Cronograma!K$2:K$30=$A11)*1)=0)*NOT(SUMPRODUCT((Cronograma!J$2:J$30=$A11)*(Cronograma!$B$2:$B$30=TRUE))>0))+((SUMPRODUCT((Cronograma!K$2:K$30=$A11)*1)=0)*NOT(SUMPRODUCT((Cronograma!L$2:L$30=$A11)*(Cronograma!$B$2:$B$30=FALSE))>0))>0),(((SUMPRODUCT((Cronograma!L$2:L$30=$A11)*1)=0)*NOT(SUMPRODUCT((Cronograma!K$2:K$30=$A11)*(Cronograma!$B$2:$B$30=TRUE))>0))+((SUMPRODUCT((Cronograma!L$2:L$30=$A11)*1)=0)*NOT(SUMPRODUCT((Cronograma!M$2:M$30=$A11)*(Cronograma!$B$2:$B$30=FALSE))>0))>0),(((SUMPRODUCT((Cronograma!M$2:M$30=$A11)*1)=0)*NOT(SUMPRODUCT((Cronograma!L$2:L$30=$A11)*(Cronograma!$B$2:$B$30=TRUE))>0))+((SUMPRODUCT((Cronograma!M$2:M$30=$A11)*1)=0)*NOT(SUMPRODUCT((Cronograma!N$2:N$30=$A11)*(Cronograma!$B$2:$B$30=FALSE))>0))>0),(((SUMPRODUCT((Cronograma!N$2:N$30=$A11)*1)=0)*NOT(SUMPRODUCT((Cronograma!M$2:M$30=$A11)*(Cronograma!$B$2:$B$30=TRUE))>0))+((SUMPRODUCT((Cronograma!N$2:N$30=$A11)*1)=0)*NOT(SUMPRODUCT((Cronograma!O$2:O$30=$A11)*(Cronograma!$B$2:$B$30=FALSE))>0))>0),(((SUMPRODUCT((Cronograma!O$2:O$30=$A11)*1)=0)*NOT(SUMPRODUCT((Cronograma!N$2:N$30=$A11)*(Cronograma!$B$2:$B$30=TRUE))>0))+((SUMPRODUCT((Cronograma!O$2:O$30=$A11)*1)=0)*NOT(SUMPRODUCT((Cronograma!P$2:P$30=$A11)*(Cronograma!$B$2:$B$30=FALSE))>0))>0),(((SUMPRODUCT((Cronograma!P$2:P$30=$A11)*1)=0)*NOT(SUMPRODUCT((Cronograma!O$2:O$30=$A11)*(Cronograma!$B$2:$B$30=TRUE))>0))+((SUMPRODUCT((Cronograma!P$2:P$30=$A11)*1)=0)*NOT(SUMPRODUCT((Cronograma!Q$2:Q$30=$A11)*(Cronograma!$B$2:$B$30=FALSE))>0))>0),((SUMPRODUCT((Cronograma!Q$2:Q$30=$A11)*1)=0)*NOT(SUMPRODUCT((Cronograma!P$2:P$30=$A11)*(Cronograma!$B$2:$B$30=TRUE))>0))) -> 0 | E11: {=_xlfn.XLOOKUP("Gisela",Cronograma!C2:C30,Cronograma!A2:A30,"")} -> 0 | F11: {=_xlfn.XLOOKUP("Gisela",Cronograma!D2:D30,Cronograma!A2:A30,"")} -> 0 | G11: {=_xlfn.XLOOKUP("Gisela",Cronograma!E2:E30,Cronograma!A2:A30,"")} -> 0 | H11: {=_xlfn.XLOOKUP("Gisela",Cronograma!F2:F30,Cronograma!A2:A30,"")} -> 0 | I11: {=_xlfn.XLOOKUP("Gisela",Cronograma!G2:G30,Cronograma!A2:A30,"")} -> 0 | J11: {=_xlfn.XLOOKUP("Gisela",Cronograma!H2:H30,Cronograma!A2:A30,"")} -> 0 | K11: {=_xlfn.XLOOKUP("Gisela",Cronograma!I2:I30,Cronograma!A2:A30,"")} -> 0 | L11: {=_xlfn.XLOOKUP("Gisela",Cronograma!J2:J30,Cronograma!A2:A30,"")} -> 0 | M11: {=_xlfn.XLOOKUP("Gisela",Cronograma!K2:K30,Cronograma!A2:A30,"")} -> 0 | N11: {=_xlfn.XLOOKUP("Gisela",Cronograma!L2:L30,Cronograma!A2:A30,"")} -> 0 | O11: {=_xlfn.XLOOKUP("Gisela",Cronograma!M2:M30,Cronograma!A2:A30,"")} -> 0 | P11: {=_xlfn.XLOOKUP("Gisela",Cronograma!N2:N30,Cronograma!A2:A30,"")} -> 0 | Q11: {=_xlfn.XLOOKUP("Gisela",Cronograma!O2:O30,Cronograma!A2:A30,"")} -> 0 | R11: {=_xlfn.XLOOKUP("Gisela",Cronograma!P2:P30,Cronograma!A2:A30,"")} -> 0 | S11: {=_xlfn.XLOOKUP("Gisela",Cronograma!Q2:Q30,Cronograma!A2:A30,"")} -> 0
